[2022-02-11 10:33:00,951]{C:\Users\User\PycharmProjects\flask-shop\venv\lib\site-packages\flask\app.py:1890}
ERROR - Exception on / [GET]
Traceback (most recent call last):
  File "C:\Users\User\PycharmProjects\flask-shop\venv\lib\site-packages\sqlalchemy\util\_collections.py", line 1020, in __call__
    return self.registry[key]
KeyError: <greenlet.greenlet object at 0x000001A10B1DAB40 (otid=0x000001A10B1F2300) current active started main>

During handling of the above exception, another exception occurred:

Traceback (most recent call last):
  File "C:\Users\User\PycharmProjects\flask-shop\venv\lib\site-packages\flask\app.py", line 2446, in wsgi_app
    response = self.full_dispatch_request()
  File "C:\Users\User\PycharmProjects\flask-shop\venv\lib\site-packages\flask\app.py", line 1951, in full_dispatch_request
    rv = self.handle_user_exception(e)
  File "C:\Users\User\PycharmProjects\flask-shop\venv\lib\site-packages\flask_restplus\api.py", line 584, in error_router
    return original_handler(e)
  File "C:\Users\User\PycharmProjects\flask-shop\venv\lib\site-packages\flask\app.py", line 1820, in handle_user_exception
    reraise(exc_type, exc_value, tb)
  File "C:\Users\User\PycharmProjects\flask-shop\venv\lib\site-packages\flask\_compat.py", line 39, in reraise
    raise value
  File "C:\Users\User\PycharmProjects\flask-shop\venv\lib\site-packages\flask\app.py", line 1949, in full_dispatch_request
    rv = self.dispatch_request()
  File "C:\Users\User\PycharmProjects\flask-shop\venv\lib\site-packages\flask\app.py", line 1935, in dispatch_request
    return self.view_functions[rule.endpoint](**req.view_args)
  File "C:\Users\User\PycharmProjects\flask-shop\flask-shop-master\flaskshop\public\views.py", line 26, in home
    products= Product.query.all()
  File "C:\Users\User\PycharmProjects\flask-shop\venv\lib\site-packages\flask_sqlalchemy\__init__.py", line 519, in __get__
    return type.query_class(mapper, session=self.sa.session())
  File "C:\Users\User\PycharmProjects\flask-shop\venv\lib\site-packages\sqlalchemy\orm\scoping.py", line 78, in __call__
    return self.registry()
  File "C:\Users\User\PycharmProjects\flask-shop\venv\lib\site-packages\sqlalchemy\util\_collections.py", line 1022, in __call__
    return self.registry.setdefault(key, self.createfunc())
  File "C:\Users\User\PycharmProjects\flask-shop\venv\lib\site-packages\sqlalchemy\orm\session.py", line 3309, in __call__
    return self.class_(**local_kw)
  File "C:\Users\User\PycharmProjects\flask-shop\venv\lib\site-packages\flask_sqlalchemy\__init__.py", line 138, in __init__
    bind = options.pop('bind', None) or db.engine
  File "C:\Users\User\PycharmProjects\flask-shop\venv\lib\site-packages\flask_sqlalchemy\__init__.py", line 937, in engine
    return self.get_engine()
  File "C:\Users\User\PycharmProjects\flask-shop\venv\lib\site-packages\flask_sqlalchemy\__init__.py", line 956, in get_engine
    return connector.get_engine()
  File "C:\Users\User\PycharmProjects\flask-shop\venv\lib\site-packages\flask_sqlalchemy\__init__.py", line 560, in get_engine
    options = self.get_options(sa_url, echo)
  File "C:\Users\User\PycharmProjects\flask-shop\venv\lib\site-packages\flask_sqlalchemy\__init__.py", line 575, in get_options
    self._sa.apply_driver_hacks(self._app, sa_url, options)
  File "C:\Users\User\PycharmProjects\flask-shop\flask-shop-master\flaskshop\extensions.py", line 147, in apply_driver_hacks
    return super().apply_driver_hacks(app, info, options)
  File "C:\Users\User\PycharmProjects\flask-shop\venv\lib\site-packages\flask_sqlalchemy\__init__.py", line 877, in apply_driver_hacks
    if sa_url.drivername.startswith('mysql'):
AttributeError: 'NoneType' object has no attribute 'drivername'
[2022-02-11 10:35:11,121]{C:\Users\User\PycharmProjects\flask-shop\venv\lib\site-packages\flask\app.py:1890}
ERROR - Exception on / [GET]
Traceback (most recent call last):
  File "C:\Users\User\PycharmProjects\flask-shop\venv\lib\site-packages\sqlalchemy\engine\base.py", line 2336, in _wrap_pool_connect
    return fn()
  File "C:\Users\User\PycharmProjects\flask-shop\venv\lib\site-packages\sqlalchemy\pool\base.py", line 364, in connect
    return _ConnectionFairy._checkout(self)
  File "C:\Users\User\PycharmProjects\flask-shop\venv\lib\site-packages\sqlalchemy\pool\base.py", line 778, in _checkout
    fairy = _ConnectionRecord.checkout(pool)
  File "C:\Users\User\PycharmProjects\flask-shop\venv\lib\site-packages\sqlalchemy\pool\base.py", line 495, in checkout
    rec = pool._do_get()
  File "C:\Users\User\PycharmProjects\flask-shop\venv\lib\site-packages\sqlalchemy\pool\impl.py", line 140, in _do_get
    self._dec_overflow()
  File "C:\Users\User\PycharmProjects\flask-shop\venv\lib\site-packages\sqlalchemy\util\langhelpers.py", line 68, in __exit__
    compat.raise_(
  File "C:\Users\User\PycharmProjects\flask-shop\venv\lib\site-packages\sqlalchemy\util\compat.py", line 182, in raise_
    raise exception
  File "C:\Users\User\PycharmProjects\flask-shop\venv\lib\site-packages\sqlalchemy\pool\impl.py", line 137, in _do_get
    return self._create_connection()
  File "C:\Users\User\PycharmProjects\flask-shop\venv\lib\site-packages\sqlalchemy\pool\base.py", line 309, in _create_connection
    return _ConnectionRecord(self)
  File "C:\Users\User\PycharmProjects\flask-shop\venv\lib\site-packages\sqlalchemy\pool\base.py", line 440, in __init__
    self.__connect(first_connect_check=True)
  File "C:\Users\User\PycharmProjects\flask-shop\venv\lib\site-packages\sqlalchemy\pool\base.py", line 661, in __connect
    pool.logger.debug("Error on connect(): %s", e)
  File "C:\Users\User\PycharmProjects\flask-shop\venv\lib\site-packages\sqlalchemy\util\langhelpers.py", line 68, in __exit__
    compat.raise_(
  File "C:\Users\User\PycharmProjects\flask-shop\venv\lib\site-packages\sqlalchemy\util\compat.py", line 182, in raise_
    raise exception
  File "C:\Users\User\PycharmProjects\flask-shop\venv\lib\site-packages\sqlalchemy\pool\base.py", line 656, in __connect
    connection = pool._invoke_creator(self)
  File "C:\Users\User\PycharmProjects\flask-shop\venv\lib\site-packages\sqlalchemy\engine\strategies.py", line 114, in connect
    return dialect.connect(*cargs, **cparams)
  File "C:\Users\User\PycharmProjects\flask-shop\venv\lib\site-packages\sqlalchemy\engine\default.py", line 508, in connect
    return self.dbapi.connect(*cargs, **cparams)
  File "C:\Users\User\PycharmProjects\flask-shop\venv\lib\site-packages\MySQLdb\__init__.py", line 130, in Connect
    return Connection(*args, **kwargs)
  File "C:\Users\User\PycharmProjects\flask-shop\venv\lib\site-packages\MySQLdb\connections.py", line 185, in __init__
    super().__init__(*args, **kwargs2)
MySQLdb._exceptions.OperationalError: (1045, "Access denied for user 'root'@'localhost' (using password: YES)")

The above exception was the direct cause of the following exception:

Traceback (most recent call last):
  File "C:\Users\User\PycharmProjects\flask-shop\venv\lib\site-packages\flask\app.py", line 2446, in wsgi_app
    response = self.full_dispatch_request()
  File "C:\Users\User\PycharmProjects\flask-shop\venv\lib\site-packages\flask\app.py", line 1951, in full_dispatch_request
    rv = self.handle_user_exception(e)
  File "C:\Users\User\PycharmProjects\flask-shop\venv\lib\site-packages\flask_restplus\api.py", line 584, in error_router
    return original_handler(e)
  File "C:\Users\User\PycharmProjects\flask-shop\venv\lib\site-packages\flask\app.py", line 1820, in handle_user_exception
    reraise(exc_type, exc_value, tb)
  File "C:\Users\User\PycharmProjects\flask-shop\venv\lib\site-packages\flask\_compat.py", line 39, in reraise
    raise value
  File "C:\Users\User\PycharmProjects\flask-shop\venv\lib\site-packages\flask\app.py", line 1949, in full_dispatch_request
    rv = self.dispatch_request()
  File "C:\Users\User\PycharmProjects\flask-shop\venv\lib\site-packages\flask\app.py", line 1935, in dispatch_request
    return self.view_functions[rule.endpoint](**req.view_args)
  File "C:\Users\User\PycharmProjects\flask-shop\flask-shop-master\flaskshop\public\views.py", line 26, in home
    products= Product.query.all()
  File "C:\Users\User\PycharmProjects\flask-shop\venv\lib\site-packages\sqlalchemy\orm\query.py", line 3373, in all
    return list(self)
  File "C:\Users\User\PycharmProjects\flask-shop\venv\lib\site-packages\sqlalchemy\orm\query.py", line 3535, in __iter__
    return self._execute_and_instances(context)
  File "C:\Users\User\PycharmProjects\flask-shop\venv\lib\site-packages\sqlalchemy\orm\query.py", line 3556, in _execute_and_instances
    conn = self._get_bind_args(
  File "C:\Users\User\PycharmProjects\flask-shop\venv\lib\site-packages\sqlalchemy\orm\query.py", line 3571, in _get_bind_args
    return fn(
  File "C:\Users\User\PycharmProjects\flask-shop\venv\lib\site-packages\sqlalchemy\orm\query.py", line 3550, in _connection_from_session
    conn = self.session.connection(**kw)
  File "C:\Users\User\PycharmProjects\flask-shop\venv\lib\site-packages\sqlalchemy\orm\session.py", line 1142, in connection
    return self._connection_for_bind(
  File "C:\Users\User\PycharmProjects\flask-shop\venv\lib\site-packages\sqlalchemy\orm\session.py", line 1150, in _connection_for_bind
    return self.transaction._connection_for_bind(
  File "C:\Users\User\PycharmProjects\flask-shop\venv\lib\site-packages\sqlalchemy\orm\session.py", line 433, in _connection_for_bind
    conn = bind._contextual_connect()
  File "C:\Users\User\PycharmProjects\flask-shop\venv\lib\site-packages\sqlalchemy\engine\base.py", line 2302, in _contextual_connect
    self._wrap_pool_connect(self.pool.connect, None),
  File "C:\Users\User\PycharmProjects\flask-shop\venv\lib\site-packages\sqlalchemy\engine\base.py", line 2339, in _wrap_pool_connect
    Connection._handle_dbapi_exception_noconnection(
  File "C:\Users\User\PycharmProjects\flask-shop\venv\lib\site-packages\sqlalchemy\engine\base.py", line 1583, in _handle_dbapi_exception_noconnection
    util.raise_(
  File "C:\Users\User\PycharmProjects\flask-shop\venv\lib\site-packages\sqlalchemy\util\compat.py", line 182, in raise_
    raise exception
  File "C:\Users\User\PycharmProjects\flask-shop\venv\lib\site-packages\sqlalchemy\engine\base.py", line 2336, in _wrap_pool_connect
    return fn()
  File "C:\Users\User\PycharmProjects\flask-shop\venv\lib\site-packages\sqlalchemy\pool\base.py", line 364, in connect
    return _ConnectionFairy._checkout(self)
  File "C:\Users\User\PycharmProjects\flask-shop\venv\lib\site-packages\sqlalchemy\pool\base.py", line 778, in _checkout
    fairy = _ConnectionRecord.checkout(pool)
  File "C:\Users\User\PycharmProjects\flask-shop\venv\lib\site-packages\sqlalchemy\pool\base.py", line 495, in checkout
    rec = pool._do_get()
  File "C:\Users\User\PycharmProjects\flask-shop\venv\lib\site-packages\sqlalchemy\pool\impl.py", line 140, in _do_get
    self._dec_overflow()
  File "C:\Users\User\PycharmProjects\flask-shop\venv\lib\site-packages\sqlalchemy\util\langhelpers.py", line 68, in __exit__
    compat.raise_(
  File "C:\Users\User\PycharmProjects\flask-shop\venv\lib\site-packages\sqlalchemy\util\compat.py", line 182, in raise_
    raise exception
  File "C:\Users\User\PycharmProjects\flask-shop\venv\lib\site-packages\sqlalchemy\pool\impl.py", line 137, in _do_get
    return self._create_connection()
  File "C:\Users\User\PycharmProjects\flask-shop\venv\lib\site-packages\sqlalchemy\pool\base.py", line 309, in _create_connection
    return _ConnectionRecord(self)
  File "C:\Users\User\PycharmProjects\flask-shop\venv\lib\site-packages\sqlalchemy\pool\base.py", line 440, in __init__
    self.__connect(first_connect_check=True)
  File "C:\Users\User\PycharmProjects\flask-shop\venv\lib\site-packages\sqlalchemy\pool\base.py", line 661, in __connect
    pool.logger.debug("Error on connect(): %s", e)
  File "C:\Users\User\PycharmProjects\flask-shop\venv\lib\site-packages\sqlalchemy\util\langhelpers.py", line 68, in __exit__
    compat.raise_(
  File "C:\Users\User\PycharmProjects\flask-shop\venv\lib\site-packages\sqlalchemy\util\compat.py", line 182, in raise_
    raise exception
  File "C:\Users\User\PycharmProjects\flask-shop\venv\lib\site-packages\sqlalchemy\pool\base.py", line 656, in __connect
    connection = pool._invoke_creator(self)
  File "C:\Users\User\PycharmProjects\flask-shop\venv\lib\site-packages\sqlalchemy\engine\strategies.py", line 114, in connect
    return dialect.connect(*cargs, **cparams)
  File "C:\Users\User\PycharmProjects\flask-shop\venv\lib\site-packages\sqlalchemy\engine\default.py", line 508, in connect
    return self.dbapi.connect(*cargs, **cparams)
  File "C:\Users\User\PycharmProjects\flask-shop\venv\lib\site-packages\MySQLdb\__init__.py", line 130, in Connect
    return Connection(*args, **kwargs)
  File "C:\Users\User\PycharmProjects\flask-shop\venv\lib\site-packages\MySQLdb\connections.py", line 185, in __init__
    super().__init__(*args, **kwargs2)
sqlalchemy.exc.OperationalError: (MySQLdb._exceptions.OperationalError) (1045, "Access denied for user 'root'@'localhost' (using password: YES)")
(Background on this error at: http://sqlalche.me/e/13/e3q8)
[2022-02-11 10:37:43,777]{C:\Users\User\PycharmProjects\flask-shop\venv\lib\site-packages\flask\app.py:1890}
ERROR - Exception on / [GET]
Traceback (most recent call last):
  File "C:\Users\User\PycharmProjects\flask-shop\venv\lib\site-packages\sqlalchemy\engine\base.py", line 2336, in _wrap_pool_connect
    return fn()
  File "C:\Users\User\PycharmProjects\flask-shop\venv\lib\site-packages\sqlalchemy\pool\base.py", line 364, in connect
    return _ConnectionFairy._checkout(self)
  File "C:\Users\User\PycharmProjects\flask-shop\venv\lib\site-packages\sqlalchemy\pool\base.py", line 778, in _checkout
    fairy = _ConnectionRecord.checkout(pool)
  File "C:\Users\User\PycharmProjects\flask-shop\venv\lib\site-packages\sqlalchemy\pool\base.py", line 495, in checkout
    rec = pool._do_get()
  File "C:\Users\User\PycharmProjects\flask-shop\venv\lib\site-packages\sqlalchemy\pool\impl.py", line 140, in _do_get
    self._dec_overflow()
  File "C:\Users\User\PycharmProjects\flask-shop\venv\lib\site-packages\sqlalchemy\util\langhelpers.py", line 68, in __exit__
    compat.raise_(
  File "C:\Users\User\PycharmProjects\flask-shop\venv\lib\site-packages\sqlalchemy\util\compat.py", line 182, in raise_
    raise exception
  File "C:\Users\User\PycharmProjects\flask-shop\venv\lib\site-packages\sqlalchemy\pool\impl.py", line 137, in _do_get
    return self._create_connection()
  File "C:\Users\User\PycharmProjects\flask-shop\venv\lib\site-packages\sqlalchemy\pool\base.py", line 309, in _create_connection
    return _ConnectionRecord(self)
  File "C:\Users\User\PycharmProjects\flask-shop\venv\lib\site-packages\sqlalchemy\pool\base.py", line 440, in __init__
    self.__connect(first_connect_check=True)
  File "C:\Users\User\PycharmProjects\flask-shop\venv\lib\site-packages\sqlalchemy\pool\base.py", line 661, in __connect
    pool.logger.debug("Error on connect(): %s", e)
  File "C:\Users\User\PycharmProjects\flask-shop\venv\lib\site-packages\sqlalchemy\util\langhelpers.py", line 68, in __exit__
    compat.raise_(
  File "C:\Users\User\PycharmProjects\flask-shop\venv\lib\site-packages\sqlalchemy\util\compat.py", line 182, in raise_
    raise exception
  File "C:\Users\User\PycharmProjects\flask-shop\venv\lib\site-packages\sqlalchemy\pool\base.py", line 656, in __connect
    connection = pool._invoke_creator(self)
  File "C:\Users\User\PycharmProjects\flask-shop\venv\lib\site-packages\sqlalchemy\engine\strategies.py", line 114, in connect
    return dialect.connect(*cargs, **cparams)
  File "C:\Users\User\PycharmProjects\flask-shop\venv\lib\site-packages\sqlalchemy\engine\default.py", line 508, in connect
    return self.dbapi.connect(*cargs, **cparams)
  File "C:\Users\User\PycharmProjects\flask-shop\venv\lib\site-packages\MySQLdb\__init__.py", line 130, in Connect
    return Connection(*args, **kwargs)
  File "C:\Users\User\PycharmProjects\flask-shop\venv\lib\site-packages\MySQLdb\connections.py", line 185, in __init__
    super().__init__(*args, **kwargs2)
MySQLdb._exceptions.OperationalError: (1045, "Access denied for user 'root'@'localhost' (using password: YES)")

The above exception was the direct cause of the following exception:

Traceback (most recent call last):
  File "C:\Users\User\PycharmProjects\flask-shop\venv\lib\site-packages\flask\app.py", line 2446, in wsgi_app
    response = self.full_dispatch_request()
  File "C:\Users\User\PycharmProjects\flask-shop\venv\lib\site-packages\flask\app.py", line 1951, in full_dispatch_request
    rv = self.handle_user_exception(e)
  File "C:\Users\User\PycharmProjects\flask-shop\venv\lib\site-packages\flask_restplus\api.py", line 584, in error_router
    return original_handler(e)
  File "C:\Users\User\PycharmProjects\flask-shop\venv\lib\site-packages\flask\app.py", line 1820, in handle_user_exception
    reraise(exc_type, exc_value, tb)
  File "C:\Users\User\PycharmProjects\flask-shop\venv\lib\site-packages\flask\_compat.py", line 39, in reraise
    raise value
  File "C:\Users\User\PycharmProjects\flask-shop\venv\lib\site-packages\flask\app.py", line 1949, in full_dispatch_request
    rv = self.dispatch_request()
  File "C:\Users\User\PycharmProjects\flask-shop\venv\lib\site-packages\flask\app.py", line 1935, in dispatch_request
    return self.view_functions[rule.endpoint](**req.view_args)
  File "C:\Users\User\PycharmProjects\flask-shop\flask-shop-master\flaskshop\public\views.py", line 26, in home
    products= Product.query.all()
  File "C:\Users\User\PycharmProjects\flask-shop\venv\lib\site-packages\sqlalchemy\orm\query.py", line 3373, in all
    return list(self)
  File "C:\Users\User\PycharmProjects\flask-shop\venv\lib\site-packages\sqlalchemy\orm\query.py", line 3535, in __iter__
    return self._execute_and_instances(context)
  File "C:\Users\User\PycharmProjects\flask-shop\venv\lib\site-packages\sqlalchemy\orm\query.py", line 3556, in _execute_and_instances
    conn = self._get_bind_args(
  File "C:\Users\User\PycharmProjects\flask-shop\venv\lib\site-packages\sqlalchemy\orm\query.py", line 3571, in _get_bind_args
    return fn(
  File "C:\Users\User\PycharmProjects\flask-shop\venv\lib\site-packages\sqlalchemy\orm\query.py", line 3550, in _connection_from_session
    conn = self.session.connection(**kw)
  File "C:\Users\User\PycharmProjects\flask-shop\venv\lib\site-packages\sqlalchemy\orm\session.py", line 1142, in connection
    return self._connection_for_bind(
  File "C:\Users\User\PycharmProjects\flask-shop\venv\lib\site-packages\sqlalchemy\orm\session.py", line 1150, in _connection_for_bind
    return self.transaction._connection_for_bind(
  File "C:\Users\User\PycharmProjects\flask-shop\venv\lib\site-packages\sqlalchemy\orm\session.py", line 433, in _connection_for_bind
    conn = bind._contextual_connect()
  File "C:\Users\User\PycharmProjects\flask-shop\venv\lib\site-packages\sqlalchemy\engine\base.py", line 2302, in _contextual_connect
    self._wrap_pool_connect(self.pool.connect, None),
  File "C:\Users\User\PycharmProjects\flask-shop\venv\lib\site-packages\sqlalchemy\engine\base.py", line 2339, in _wrap_pool_connect
    Connection._handle_dbapi_exception_noconnection(
  File "C:\Users\User\PycharmProjects\flask-shop\venv\lib\site-packages\sqlalchemy\engine\base.py", line 1583, in _handle_dbapi_exception_noconnection
    util.raise_(
  File "C:\Users\User\PycharmProjects\flask-shop\venv\lib\site-packages\sqlalchemy\util\compat.py", line 182, in raise_
    raise exception
  File "C:\Users\User\PycharmProjects\flask-shop\venv\lib\site-packages\sqlalchemy\engine\base.py", line 2336, in _wrap_pool_connect
    return fn()
  File "C:\Users\User\PycharmProjects\flask-shop\venv\lib\site-packages\sqlalchemy\pool\base.py", line 364, in connect
    return _ConnectionFairy._checkout(self)
  File "C:\Users\User\PycharmProjects\flask-shop\venv\lib\site-packages\sqlalchemy\pool\base.py", line 778, in _checkout
    fairy = _ConnectionRecord.checkout(pool)
  File "C:\Users\User\PycharmProjects\flask-shop\venv\lib\site-packages\sqlalchemy\pool\base.py", line 495, in checkout
    rec = pool._do_get()
  File "C:\Users\User\PycharmProjects\flask-shop\venv\lib\site-packages\sqlalchemy\pool\impl.py", line 140, in _do_get
    self._dec_overflow()
  File "C:\Users\User\PycharmProjects\flask-shop\venv\lib\site-packages\sqlalchemy\util\langhelpers.py", line 68, in __exit__
    compat.raise_(
  File "C:\Users\User\PycharmProjects\flask-shop\venv\lib\site-packages\sqlalchemy\util\compat.py", line 182, in raise_
    raise exception
  File "C:\Users\User\PycharmProjects\flask-shop\venv\lib\site-packages\sqlalchemy\pool\impl.py", line 137, in _do_get
    return self._create_connection()
  File "C:\Users\User\PycharmProjects\flask-shop\venv\lib\site-packages\sqlalchemy\pool\base.py", line 309, in _create_connection
    return _ConnectionRecord(self)
  File "C:\Users\User\PycharmProjects\flask-shop\venv\lib\site-packages\sqlalchemy\pool\base.py", line 440, in __init__
    self.__connect(first_connect_check=True)
  File "C:\Users\User\PycharmProjects\flask-shop\venv\lib\site-packages\sqlalchemy\pool\base.py", line 661, in __connect
    pool.logger.debug("Error on connect(): %s", e)
  File "C:\Users\User\PycharmProjects\flask-shop\venv\lib\site-packages\sqlalchemy\util\langhelpers.py", line 68, in __exit__
    compat.raise_(
  File "C:\Users\User\PycharmProjects\flask-shop\venv\lib\site-packages\sqlalchemy\util\compat.py", line 182, in raise_
    raise exception
  File "C:\Users\User\PycharmProjects\flask-shop\venv\lib\site-packages\sqlalchemy\pool\base.py", line 656, in __connect
    connection = pool._invoke_creator(self)
  File "C:\Users\User\PycharmProjects\flask-shop\venv\lib\site-packages\sqlalchemy\engine\strategies.py", line 114, in connect
    return dialect.connect(*cargs, **cparams)
  File "C:\Users\User\PycharmProjects\flask-shop\venv\lib\site-packages\sqlalchemy\engine\default.py", line 508, in connect
    return self.dbapi.connect(*cargs, **cparams)
  File "C:\Users\User\PycharmProjects\flask-shop\venv\lib\site-packages\MySQLdb\__init__.py", line 130, in Connect
    return Connection(*args, **kwargs)
  File "C:\Users\User\PycharmProjects\flask-shop\venv\lib\site-packages\MySQLdb\connections.py", line 185, in __init__
    super().__init__(*args, **kwargs2)
sqlalchemy.exc.OperationalError: (MySQLdb._exceptions.OperationalError) (1045, "Access denied for user 'root'@'localhost' (using password: YES)")
(Background on this error at: http://sqlalche.me/e/13/e3q8)
[2022-02-11 10:42:14,399]{C:\Users\User\PycharmProjects\flask-shop\venv\lib\site-packages\flask\app.py:1890}
ERROR - Exception on / [GET]
Traceback (most recent call last):
  File "C:\Users\User\PycharmProjects\flask-shop\venv\lib\site-packages\sqlalchemy\engine\base.py", line 2336, in _wrap_pool_connect
    return fn()
  File "C:\Users\User\PycharmProjects\flask-shop\venv\lib\site-packages\sqlalchemy\pool\base.py", line 364, in connect
    return _ConnectionFairy._checkout(self)
  File "C:\Users\User\PycharmProjects\flask-shop\venv\lib\site-packages\sqlalchemy\pool\base.py", line 778, in _checkout
    fairy = _ConnectionRecord.checkout(pool)
  File "C:\Users\User\PycharmProjects\flask-shop\venv\lib\site-packages\sqlalchemy\pool\base.py", line 495, in checkout
    rec = pool._do_get()
  File "C:\Users\User\PycharmProjects\flask-shop\venv\lib\site-packages\sqlalchemy\pool\impl.py", line 140, in _do_get
    self._dec_overflow()
  File "C:\Users\User\PycharmProjects\flask-shop\venv\lib\site-packages\sqlalchemy\util\langhelpers.py", line 68, in __exit__
    compat.raise_(
  File "C:\Users\User\PycharmProjects\flask-shop\venv\lib\site-packages\sqlalchemy\util\compat.py", line 182, in raise_
    raise exception
  File "C:\Users\User\PycharmProjects\flask-shop\venv\lib\site-packages\sqlalchemy\pool\impl.py", line 137, in _do_get
    return self._create_connection()
  File "C:\Users\User\PycharmProjects\flask-shop\venv\lib\site-packages\sqlalchemy\pool\base.py", line 309, in _create_connection
    return _ConnectionRecord(self)
  File "C:\Users\User\PycharmProjects\flask-shop\venv\lib\site-packages\sqlalchemy\pool\base.py", line 440, in __init__
    self.__connect(first_connect_check=True)
  File "C:\Users\User\PycharmProjects\flask-shop\venv\lib\site-packages\sqlalchemy\pool\base.py", line 661, in __connect
    pool.logger.debug("Error on connect(): %s", e)
  File "C:\Users\User\PycharmProjects\flask-shop\venv\lib\site-packages\sqlalchemy\util\langhelpers.py", line 68, in __exit__
    compat.raise_(
  File "C:\Users\User\PycharmProjects\flask-shop\venv\lib\site-packages\sqlalchemy\util\compat.py", line 182, in raise_
    raise exception
  File "C:\Users\User\PycharmProjects\flask-shop\venv\lib\site-packages\sqlalchemy\pool\base.py", line 656, in __connect
    connection = pool._invoke_creator(self)
  File "C:\Users\User\PycharmProjects\flask-shop\venv\lib\site-packages\sqlalchemy\engine\strategies.py", line 114, in connect
    return dialect.connect(*cargs, **cparams)
  File "C:\Users\User\PycharmProjects\flask-shop\venv\lib\site-packages\sqlalchemy\engine\default.py", line 508, in connect
    return self.dbapi.connect(*cargs, **cparams)
  File "C:\Users\User\PycharmProjects\flask-shop\venv\lib\site-packages\MySQLdb\__init__.py", line 130, in Connect
    return Connection(*args, **kwargs)
  File "C:\Users\User\PycharmProjects\flask-shop\venv\lib\site-packages\MySQLdb\connections.py", line 185, in __init__
    super().__init__(*args, **kwargs2)
MySQLdb._exceptions.OperationalError: (1045, "Access denied for user 'root'@'localhost' (using password: YES)")

The above exception was the direct cause of the following exception:

Traceback (most recent call last):
  File "C:\Users\User\PycharmProjects\flask-shop\venv\lib\site-packages\flask\app.py", line 2446, in wsgi_app
    response = self.full_dispatch_request()
  File "C:\Users\User\PycharmProjects\flask-shop\venv\lib\site-packages\flask\app.py", line 1951, in full_dispatch_request
    rv = self.handle_user_exception(e)
  File "C:\Users\User\PycharmProjects\flask-shop\venv\lib\site-packages\flask_restplus\api.py", line 584, in error_router
    return original_handler(e)
  File "C:\Users\User\PycharmProjects\flask-shop\venv\lib\site-packages\flask\app.py", line 1820, in handle_user_exception
    reraise(exc_type, exc_value, tb)
  File "C:\Users\User\PycharmProjects\flask-shop\venv\lib\site-packages\flask\_compat.py", line 39, in reraise
    raise value
  File "C:\Users\User\PycharmProjects\flask-shop\venv\lib\site-packages\flask\app.py", line 1949, in full_dispatch_request
    rv = self.dispatch_request()
  File "C:\Users\User\PycharmProjects\flask-shop\venv\lib\site-packages\flask\app.py", line 1935, in dispatch_request
    return self.view_functions[rule.endpoint](**req.view_args)
  File "C:\Users\User\PycharmProjects\flask-shop\flask-shop-master\flaskshop\public\views.py", line 26, in home
    products= Product.query.all()
  File "C:\Users\User\PycharmProjects\flask-shop\venv\lib\site-packages\sqlalchemy\orm\query.py", line 3373, in all
    return list(self)
  File "C:\Users\User\PycharmProjects\flask-shop\venv\lib\site-packages\sqlalchemy\orm\query.py", line 3535, in __iter__
    return self._execute_and_instances(context)
  File "C:\Users\User\PycharmProjects\flask-shop\venv\lib\site-packages\sqlalchemy\orm\query.py", line 3556, in _execute_and_instances
    conn = self._get_bind_args(
  File "C:\Users\User\PycharmProjects\flask-shop\venv\lib\site-packages\sqlalchemy\orm\query.py", line 3571, in _get_bind_args
    return fn(
  File "C:\Users\User\PycharmProjects\flask-shop\venv\lib\site-packages\sqlalchemy\orm\query.py", line 3550, in _connection_from_session
    conn = self.session.connection(**kw)
  File "C:\Users\User\PycharmProjects\flask-shop\venv\lib\site-packages\sqlalchemy\orm\session.py", line 1142, in connection
    return self._connection_for_bind(
  File "C:\Users\User\PycharmProjects\flask-shop\venv\lib\site-packages\sqlalchemy\orm\session.py", line 1150, in _connection_for_bind
    return self.transaction._connection_for_bind(
  File "C:\Users\User\PycharmProjects\flask-shop\venv\lib\site-packages\sqlalchemy\orm\session.py", line 433, in _connection_for_bind
    conn = bind._contextual_connect()
  File "C:\Users\User\PycharmProjects\flask-shop\venv\lib\site-packages\sqlalchemy\engine\base.py", line 2302, in _contextual_connect
    self._wrap_pool_connect(self.pool.connect, None),
  File "C:\Users\User\PycharmProjects\flask-shop\venv\lib\site-packages\sqlalchemy\engine\base.py", line 2339, in _wrap_pool_connect
    Connection._handle_dbapi_exception_noconnection(
  File "C:\Users\User\PycharmProjects\flask-shop\venv\lib\site-packages\sqlalchemy\engine\base.py", line 1583, in _handle_dbapi_exception_noconnection
    util.raise_(
  File "C:\Users\User\PycharmProjects\flask-shop\venv\lib\site-packages\sqlalchemy\util\compat.py", line 182, in raise_
    raise exception
  File "C:\Users\User\PycharmProjects\flask-shop\venv\lib\site-packages\sqlalchemy\engine\base.py", line 2336, in _wrap_pool_connect
    return fn()
  File "C:\Users\User\PycharmProjects\flask-shop\venv\lib\site-packages\sqlalchemy\pool\base.py", line 364, in connect
    return _ConnectionFairy._checkout(self)
  File "C:\Users\User\PycharmProjects\flask-shop\venv\lib\site-packages\sqlalchemy\pool\base.py", line 778, in _checkout
    fairy = _ConnectionRecord.checkout(pool)
  File "C:\Users\User\PycharmProjects\flask-shop\venv\lib\site-packages\sqlalchemy\pool\base.py", line 495, in checkout
    rec = pool._do_get()
  File "C:\Users\User\PycharmProjects\flask-shop\venv\lib\site-packages\sqlalchemy\pool\impl.py", line 140, in _do_get
    self._dec_overflow()
  File "C:\Users\User\PycharmProjects\flask-shop\venv\lib\site-packages\sqlalchemy\util\langhelpers.py", line 68, in __exit__
    compat.raise_(
  File "C:\Users\User\PycharmProjects\flask-shop\venv\lib\site-packages\sqlalchemy\util\compat.py", line 182, in raise_
    raise exception
  File "C:\Users\User\PycharmProjects\flask-shop\venv\lib\site-packages\sqlalchemy\pool\impl.py", line 137, in _do_get
    return self._create_connection()
  File "C:\Users\User\PycharmProjects\flask-shop\venv\lib\site-packages\sqlalchemy\pool\base.py", line 309, in _create_connection
    return _ConnectionRecord(self)
  File "C:\Users\User\PycharmProjects\flask-shop\venv\lib\site-packages\sqlalchemy\pool\base.py", line 440, in __init__
    self.__connect(first_connect_check=True)
  File "C:\Users\User\PycharmProjects\flask-shop\venv\lib\site-packages\sqlalchemy\pool\base.py", line 661, in __connect
    pool.logger.debug("Error on connect(): %s", e)
  File "C:\Users\User\PycharmProjects\flask-shop\venv\lib\site-packages\sqlalchemy\util\langhelpers.py", line 68, in __exit__
    compat.raise_(
  File "C:\Users\User\PycharmProjects\flask-shop\venv\lib\site-packages\sqlalchemy\util\compat.py", line 182, in raise_
    raise exception
  File "C:\Users\User\PycharmProjects\flask-shop\venv\lib\site-packages\sqlalchemy\pool\base.py", line 656, in __connect
    connection = pool._invoke_creator(self)
  File "C:\Users\User\PycharmProjects\flask-shop\venv\lib\site-packages\sqlalchemy\engine\strategies.py", line 114, in connect
    return dialect.connect(*cargs, **cparams)
  File "C:\Users\User\PycharmProjects\flask-shop\venv\lib\site-packages\sqlalchemy\engine\default.py", line 508, in connect
    return self.dbapi.connect(*cargs, **cparams)
  File "C:\Users\User\PycharmProjects\flask-shop\venv\lib\site-packages\MySQLdb\__init__.py", line 130, in Connect
    return Connection(*args, **kwargs)
  File "C:\Users\User\PycharmProjects\flask-shop\venv\lib\site-packages\MySQLdb\connections.py", line 185, in __init__
    super().__init__(*args, **kwargs2)
sqlalchemy.exc.OperationalError: (MySQLdb._exceptions.OperationalError) (1045, "Access denied for user 'root'@'localhost' (using password: YES)")
(Background on this error at: http://sqlalche.me/e/13/e3q8)
[2022-02-11 10:46:00,004]{C:\Users\User\PycharmProjects\flask-shop\venv\lib\site-packages\flask\app.py:1890}
ERROR - Exception on / [GET]
Traceback (most recent call last):
  File "C:\Users\User\PycharmProjects\flask-shop\venv\lib\site-packages\sqlalchemy\engine\base.py", line 2336, in _wrap_pool_connect
    return fn()
  File "C:\Users\User\PycharmProjects\flask-shop\venv\lib\site-packages\sqlalchemy\pool\base.py", line 364, in connect
    return _ConnectionFairy._checkout(self)
  File "C:\Users\User\PycharmProjects\flask-shop\venv\lib\site-packages\sqlalchemy\pool\base.py", line 778, in _checkout
    fairy = _ConnectionRecord.checkout(pool)
  File "C:\Users\User\PycharmProjects\flask-shop\venv\lib\site-packages\sqlalchemy\pool\base.py", line 495, in checkout
    rec = pool._do_get()
  File "C:\Users\User\PycharmProjects\flask-shop\venv\lib\site-packages\sqlalchemy\pool\impl.py", line 140, in _do_get
    self._dec_overflow()
  File "C:\Users\User\PycharmProjects\flask-shop\venv\lib\site-packages\sqlalchemy\util\langhelpers.py", line 68, in __exit__
    compat.raise_(
  File "C:\Users\User\PycharmProjects\flask-shop\venv\lib\site-packages\sqlalchemy\util\compat.py", line 182, in raise_
    raise exception
  File "C:\Users\User\PycharmProjects\flask-shop\venv\lib\site-packages\sqlalchemy\pool\impl.py", line 137, in _do_get
    return self._create_connection()
  File "C:\Users\User\PycharmProjects\flask-shop\venv\lib\site-packages\sqlalchemy\pool\base.py", line 309, in _create_connection
    return _ConnectionRecord(self)
  File "C:\Users\User\PycharmProjects\flask-shop\venv\lib\site-packages\sqlalchemy\pool\base.py", line 440, in __init__
    self.__connect(first_connect_check=True)
  File "C:\Users\User\PycharmProjects\flask-shop\venv\lib\site-packages\sqlalchemy\pool\base.py", line 661, in __connect
    pool.logger.debug("Error on connect(): %s", e)
  File "C:\Users\User\PycharmProjects\flask-shop\venv\lib\site-packages\sqlalchemy\util\langhelpers.py", line 68, in __exit__
    compat.raise_(
  File "C:\Users\User\PycharmProjects\flask-shop\venv\lib\site-packages\sqlalchemy\util\compat.py", line 182, in raise_
    raise exception
  File "C:\Users\User\PycharmProjects\flask-shop\venv\lib\site-packages\sqlalchemy\pool\base.py", line 656, in __connect
    connection = pool._invoke_creator(self)
  File "C:\Users\User\PycharmProjects\flask-shop\venv\lib\site-packages\sqlalchemy\engine\strategies.py", line 114, in connect
    return dialect.connect(*cargs, **cparams)
  File "C:\Users\User\PycharmProjects\flask-shop\venv\lib\site-packages\sqlalchemy\engine\default.py", line 508, in connect
    return self.dbapi.connect(*cargs, **cparams)
  File "C:\Users\User\PycharmProjects\flask-shop\venv\lib\site-packages\MySQLdb\__init__.py", line 130, in Connect
    return Connection(*args, **kwargs)
  File "C:\Users\User\PycharmProjects\flask-shop\venv\lib\site-packages\MySQLdb\connections.py", line 185, in __init__
    super().__init__(*args, **kwargs2)
MySQLdb._exceptions.OperationalError: (2005, "Unknown MySQL server host ' localhost' (11001)")

The above exception was the direct cause of the following exception:

Traceback (most recent call last):
  File "C:\Users\User\PycharmProjects\flask-shop\venv\lib\site-packages\flask\app.py", line 2446, in wsgi_app
    response = self.full_dispatch_request()
  File "C:\Users\User\PycharmProjects\flask-shop\venv\lib\site-packages\flask\app.py", line 1951, in full_dispatch_request
    rv = self.handle_user_exception(e)
  File "C:\Users\User\PycharmProjects\flask-shop\venv\lib\site-packages\flask_restplus\api.py", line 584, in error_router
    return original_handler(e)
  File "C:\Users\User\PycharmProjects\flask-shop\venv\lib\site-packages\flask\app.py", line 1820, in handle_user_exception
    reraise(exc_type, exc_value, tb)
  File "C:\Users\User\PycharmProjects\flask-shop\venv\lib\site-packages\flask\_compat.py", line 39, in reraise
    raise value
  File "C:\Users\User\PycharmProjects\flask-shop\venv\lib\site-packages\flask\app.py", line 1949, in full_dispatch_request
    rv = self.dispatch_request()
  File "C:\Users\User\PycharmProjects\flask-shop\venv\lib\site-packages\flask\app.py", line 1935, in dispatch_request
    return self.view_functions[rule.endpoint](**req.view_args)
  File "C:\Users\User\PycharmProjects\flask-shop\flask-shop-master\flaskshop\public\views.py", line 26, in home
    products= Product.query.all()
  File "C:\Users\User\PycharmProjects\flask-shop\venv\lib\site-packages\sqlalchemy\orm\query.py", line 3373, in all
    return list(self)
  File "C:\Users\User\PycharmProjects\flask-shop\venv\lib\site-packages\sqlalchemy\orm\query.py", line 3535, in __iter__
    return self._execute_and_instances(context)
  File "C:\Users\User\PycharmProjects\flask-shop\venv\lib\site-packages\sqlalchemy\orm\query.py", line 3556, in _execute_and_instances
    conn = self._get_bind_args(
  File "C:\Users\User\PycharmProjects\flask-shop\venv\lib\site-packages\sqlalchemy\orm\query.py", line 3571, in _get_bind_args
    return fn(
  File "C:\Users\User\PycharmProjects\flask-shop\venv\lib\site-packages\sqlalchemy\orm\query.py", line 3550, in _connection_from_session
    conn = self.session.connection(**kw)
  File "C:\Users\User\PycharmProjects\flask-shop\venv\lib\site-packages\sqlalchemy\orm\session.py", line 1142, in connection
    return self._connection_for_bind(
  File "C:\Users\User\PycharmProjects\flask-shop\venv\lib\site-packages\sqlalchemy\orm\session.py", line 1150, in _connection_for_bind
    return self.transaction._connection_for_bind(
  File "C:\Users\User\PycharmProjects\flask-shop\venv\lib\site-packages\sqlalchemy\orm\session.py", line 433, in _connection_for_bind
    conn = bind._contextual_connect()
  File "C:\Users\User\PycharmProjects\flask-shop\venv\lib\site-packages\sqlalchemy\engine\base.py", line 2302, in _contextual_connect
    self._wrap_pool_connect(self.pool.connect, None),
  File "C:\Users\User\PycharmProjects\flask-shop\venv\lib\site-packages\sqlalchemy\engine\base.py", line 2339, in _wrap_pool_connect
    Connection._handle_dbapi_exception_noconnection(
  File "C:\Users\User\PycharmProjects\flask-shop\venv\lib\site-packages\sqlalchemy\engine\base.py", line 1583, in _handle_dbapi_exception_noconnection
    util.raise_(
  File "C:\Users\User\PycharmProjects\flask-shop\venv\lib\site-packages\sqlalchemy\util\compat.py", line 182, in raise_
    raise exception
  File "C:\Users\User\PycharmProjects\flask-shop\venv\lib\site-packages\sqlalchemy\engine\base.py", line 2336, in _wrap_pool_connect
    return fn()
  File "C:\Users\User\PycharmProjects\flask-shop\venv\lib\site-packages\sqlalchemy\pool\base.py", line 364, in connect
    return _ConnectionFairy._checkout(self)
  File "C:\Users\User\PycharmProjects\flask-shop\venv\lib\site-packages\sqlalchemy\pool\base.py", line 778, in _checkout
    fairy = _ConnectionRecord.checkout(pool)
  File "C:\Users\User\PycharmProjects\flask-shop\venv\lib\site-packages\sqlalchemy\pool\base.py", line 495, in checkout
    rec = pool._do_get()
  File "C:\Users\User\PycharmProjects\flask-shop\venv\lib\site-packages\sqlalchemy\pool\impl.py", line 140, in _do_get
    self._dec_overflow()
  File "C:\Users\User\PycharmProjects\flask-shop\venv\lib\site-packages\sqlalchemy\util\langhelpers.py", line 68, in __exit__
    compat.raise_(
  File "C:\Users\User\PycharmProjects\flask-shop\venv\lib\site-packages\sqlalchemy\util\compat.py", line 182, in raise_
    raise exception
  File "C:\Users\User\PycharmProjects\flask-shop\venv\lib\site-packages\sqlalchemy\pool\impl.py", line 137, in _do_get
    return self._create_connection()
  File "C:\Users\User\PycharmProjects\flask-shop\venv\lib\site-packages\sqlalchemy\pool\base.py", line 309, in _create_connection
    return _ConnectionRecord(self)
  File "C:\Users\User\PycharmProjects\flask-shop\venv\lib\site-packages\sqlalchemy\pool\base.py", line 440, in __init__
    self.__connect(first_connect_check=True)
  File "C:\Users\User\PycharmProjects\flask-shop\venv\lib\site-packages\sqlalchemy\pool\base.py", line 661, in __connect
    pool.logger.debug("Error on connect(): %s", e)
  File "C:\Users\User\PycharmProjects\flask-shop\venv\lib\site-packages\sqlalchemy\util\langhelpers.py", line 68, in __exit__
    compat.raise_(
  File "C:\Users\User\PycharmProjects\flask-shop\venv\lib\site-packages\sqlalchemy\util\compat.py", line 182, in raise_
    raise exception
  File "C:\Users\User\PycharmProjects\flask-shop\venv\lib\site-packages\sqlalchemy\pool\base.py", line 656, in __connect
    connection = pool._invoke_creator(self)
  File "C:\Users\User\PycharmProjects\flask-shop\venv\lib\site-packages\sqlalchemy\engine\strategies.py", line 114, in connect
    return dialect.connect(*cargs, **cparams)
  File "C:\Users\User\PycharmProjects\flask-shop\venv\lib\site-packages\sqlalchemy\engine\default.py", line 508, in connect
    return self.dbapi.connect(*cargs, **cparams)
  File "C:\Users\User\PycharmProjects\flask-shop\venv\lib\site-packages\MySQLdb\__init__.py", line 130, in Connect
    return Connection(*args, **kwargs)
  File "C:\Users\User\PycharmProjects\flask-shop\venv\lib\site-packages\MySQLdb\connections.py", line 185, in __init__
    super().__init__(*args, **kwargs2)
sqlalchemy.exc.OperationalError: (MySQLdb._exceptions.OperationalError) (2005, "Unknown MySQL server host ' localhost' (11001)")
(Background on this error at: http://sqlalche.me/e/13/e3q8)
[2022-02-13 17:57:10,204]{C:\Users\User\PycharmProjects\flask-shop\venv\lib\site-packages\flask\app.py:1890}
ERROR - Exception on /products/category/77 [GET]
Traceback (most recent call last):
  File "C:\Users\User\PycharmProjects\flask-shop\venv\lib\site-packages\flask\app.py", line 2446, in wsgi_app
    response = self.full_dispatch_request()
  File "C:\Users\User\PycharmProjects\flask-shop\venv\lib\site-packages\flask\app.py", line 1951, in full_dispatch_request
    rv = self.handle_user_exception(e)
  File "C:\Users\User\PycharmProjects\flask-shop\venv\lib\site-packages\flask_restplus\api.py", line 584, in error_router
    return original_handler(e)
  File "C:\Users\User\PycharmProjects\flask-shop\venv\lib\site-packages\flask\app.py", line 1820, in handle_user_exception
    reraise(exc_type, exc_value, tb)
  File "C:\Users\User\PycharmProjects\flask-shop\venv\lib\site-packages\flask\_compat.py", line 39, in reraise
    raise value
  File "C:\Users\User\PycharmProjects\flask-shop\venv\lib\site-packages\flask\app.py", line 1949, in full_dispatch_request
    rv = self.dispatch_request()
  File "C:\Users\User\PycharmProjects\flask-shop\venv\lib\site-packages\flask\app.py", line 1935, in dispatch_request
    return self.view_functions[rule.endpoint](**req.view_args)
  File "C:\Users\User\PycharmProjects\flask-shop\flask-shop-master\flaskshop\product\views.py", line 84, in show_category
    return render_template("category/index.html", **ctx)
  File "C:\Users\User\PycharmProjects\flask-shop\venv\lib\site-packages\flask\templating.py", line 137, in render_template
    return _render(
  File "C:\Users\User\PycharmProjects\flask-shop\venv\lib\site-packages\flask\templating.py", line 120, in _render
    rv = template.render(context)
  File "C:\Users\User\PycharmProjects\flask-shop\venv\lib\site-packages\jinja2\environment.py", line 1090, in render
    self.environment.handle_exception()
  File "C:\Users\User\PycharmProjects\flask-shop\venv\lib\site-packages\jinja2\environment.py", line 832, in handle_exception
    reraise(*rewrite_traceback_stack(source=source))
  File "C:\Users\User\PycharmProjects\flask-shop\venv\lib\site-packages\jinja2\_compat.py", line 28, in reraise
    raise value.with_traceback(tb)
  File "C:\Users\User\PycharmProjects\flask-shop\flask-shop-master\flaskshop\templates\category\index.html", line 3, in top-level template code
    {% extends "products/product_list_base.html" %}
  File "C:\Users\User\PycharmProjects\flask-shop\flask-shop-master\flaskshop\templates\products\product_list_base.html", line 130, in top-level template code
    {% import 'dashboard/_vendor.html' as vendor %}
  File "C:\Users\User\PycharmProjects\flask-shop\flask-shop-master\flaskshop\templates\base.html", line 222, in top-level template code
    {% block content %}
  File "C:\Users\User\PycharmProjects\flask-shop\flask-shop-master\flaskshop\templates\products\product_list_base.html", line 151, in block "content"
    {% include('products/product_table.html') %}
  File "C:\Users\User\PycharmProjects\flask-shop\flask-shop-master\flaskshop\templates\products\product_table.html", line 5, in top-level template code
    {% include('products/item_front.html') %}
  File "C:\Users\User\PycharmProjects\flask-shop\venv\lib\site-packages\jinja2\environment.py", line 832, in handle_exception
    reraise(*rewrite_traceback_stack(source=source))
  File "C:\Users\User\PycharmProjects\flask-shop\venv\lib\site-packages\jinja2\_compat.py", line 28, in reraise
    raise value.with_traceback(tb)
  File "C:\Users\User\PycharmProjects\flask-shop\flask-shop-master\flaskshop\templates\products\item_front.html", line 71, in template
    {% endif  %}
jinja2.exceptions.TemplateSyntaxError: Unexpected end of template. Jinja was looking for the following tags: 'elif' or 'else' or 'endif'. The innermost block that needs to be closed is 'if'.
[2022-02-13 20:59:11,406]{C:\Users\User\PycharmProjects\flask-shop\venv\lib\site-packages\flask\app.py:1890}
ERROR - Exception on /dashboard/products/395/edit [POST]
Traceback (most recent call last):
  File "C:\Users\User\PycharmProjects\flask-shop\venv\lib\site-packages\flask\app.py", line 2446, in wsgi_app
    response = self.full_dispatch_request()
  File "C:\Users\User\PycharmProjects\flask-shop\venv\lib\site-packages\flask\app.py", line 1951, in full_dispatch_request
    rv = self.handle_user_exception(e)
  File "C:\Users\User\PycharmProjects\flask-shop\venv\lib\site-packages\flask_restplus\api.py", line 584, in error_router
    return original_handler(e)
  File "C:\Users\User\PycharmProjects\flask-shop\venv\lib\site-packages\flask\app.py", line 1820, in handle_user_exception
    reraise(exc_type, exc_value, tb)
  File "C:\Users\User\PycharmProjects\flask-shop\venv\lib\site-packages\flask\_compat.py", line 39, in reraise
    raise value
  File "C:\Users\User\PycharmProjects\flask-shop\venv\lib\site-packages\flask\app.py", line 1949, in full_dispatch_request
    rv = self.dispatch_request()
  File "C:\Users\User\PycharmProjects\flask-shop\venv\lib\site-packages\flask\app.py", line 1935, in dispatch_request
    return self.view_functions[rule.endpoint](**req.view_args)
  File "C:\Users\User\PycharmProjects\flask-shop\flask-shop-master\flaskshop\dashboard\views\product.py", line 423, in product_manage
    product.product_type= product_type
AttributeError: can't set attribute
[2022-02-13 21:01:44,718]{C:\Users\User\PycharmProjects\flask-shop\venv\lib\site-packages\flask\app.py:1890}
ERROR - Exception on /dashboard/products/395/edit [POST]
Traceback (most recent call last):
  File "C:\Users\User\PycharmProjects\flask-shop\venv\lib\site-packages\flask\app.py", line 2446, in wsgi_app
    response = self.full_dispatch_request()
  File "C:\Users\User\PycharmProjects\flask-shop\venv\lib\site-packages\flask\app.py", line 1951, in full_dispatch_request
    rv = self.handle_user_exception(e)
  File "C:\Users\User\PycharmProjects\flask-shop\venv\lib\site-packages\flask_restplus\api.py", line 584, in error_router
    return original_handler(e)
  File "C:\Users\User\PycharmProjects\flask-shop\venv\lib\site-packages\flask\app.py", line 1820, in handle_user_exception
    reraise(exc_type, exc_value, tb)
  File "C:\Users\User\PycharmProjects\flask-shop\venv\lib\site-packages\flask\_compat.py", line 39, in reraise
    raise value
  File "C:\Users\User\PycharmProjects\flask-shop\venv\lib\site-packages\flask\app.py", line 1949, in full_dispatch_request
    rv = self.dispatch_request()
  File "C:\Users\User\PycharmProjects\flask-shop\venv\lib\site-packages\flask\app.py", line 1935, in dispatch_request
    return self.view_functions[rule.endpoint](**req.view_args)
  File "C:\Users\User\PycharmProjects\flask-shop\flask-shop-master\flaskshop\dashboard\views\product.py", line 423, in product_manage
AttributeError: can't set attribute
[2022-02-13 21:11:28,973]{C:\Users\User\PycharmProjects\flask-shop\venv\lib\site-packages\flask\app.py:1890}
ERROR - Exception on /dashboard/products/395/edit [POST]
Traceback (most recent call last):
  File "C:\Users\User\PycharmProjects\flask-shop\venv\lib\site-packages\flask\app.py", line 2446, in wsgi_app
    response = self.full_dispatch_request()
  File "C:\Users\User\PycharmProjects\flask-shop\venv\lib\site-packages\flask\app.py", line 1951, in full_dispatch_request
    rv = self.handle_user_exception(e)
  File "C:\Users\User\PycharmProjects\flask-shop\venv\lib\site-packages\flask_restplus\api.py", line 584, in error_router
    return original_handler(e)
  File "C:\Users\User\PycharmProjects\flask-shop\venv\lib\site-packages\flask\app.py", line 1820, in handle_user_exception
    reraise(exc_type, exc_value, tb)
  File "C:\Users\User\PycharmProjects\flask-shop\venv\lib\site-packages\flask\_compat.py", line 39, in reraise
    raise value
  File "C:\Users\User\PycharmProjects\flask-shop\venv\lib\site-packages\flask\app.py", line 1949, in full_dispatch_request
    rv = self.dispatch_request()
  File "C:\Users\User\PycharmProjects\flask-shop\venv\lib\site-packages\flask\app.py", line 1935, in dispatch_request
    return self.view_functions[rule.endpoint](**req.view_args)
  File "C:\Users\User\PycharmProjects\flask-shop\flask-shop-master\flaskshop\dashboard\views\product.py", line 409, in product_manage
    product_type= product.product_type()
TypeError: 'ProductType' object is not callable
[2022-02-13 21:18:45,975]{C:\Users\User\PycharmProjects\flask-shop\venv\lib\site-packages\flask\app.py:1890}
ERROR - Exception on /dashboard/products/90/edit [POST]
Traceback (most recent call last):
  File "C:\Users\User\PycharmProjects\flask-shop\venv\lib\site-packages\flask\app.py", line 2446, in wsgi_app
    response = self.full_dispatch_request()
  File "C:\Users\User\PycharmProjects\flask-shop\venv\lib\site-packages\flask\app.py", line 1951, in full_dispatch_request
    rv = self.handle_user_exception(e)
  File "C:\Users\User\PycharmProjects\flask-shop\venv\lib\site-packages\flask_restplus\api.py", line 584, in error_router
    return original_handler(e)
  File "C:\Users\User\PycharmProjects\flask-shop\venv\lib\site-packages\flask\app.py", line 1820, in handle_user_exception
    reraise(exc_type, exc_value, tb)
  File "C:\Users\User\PycharmProjects\flask-shop\venv\lib\site-packages\flask\_compat.py", line 39, in reraise
    raise value
  File "C:\Users\User\PycharmProjects\flask-shop\venv\lib\site-packages\flask\app.py", line 1949, in full_dispatch_request
    rv = self.dispatch_request()
  File "C:\Users\User\PycharmProjects\flask-shop\venv\lib\site-packages\flask\app.py", line 1935, in dispatch_request
    return self.view_functions[rule.endpoint](**req.view_args)
  File "C:\Users\User\PycharmProjects\flask-shop\flask-shop-master\flaskshop\dashboard\views\product.py", line 409, in product_manage
    product_type= product.product_type()
TypeError: 'ProductType' object is not callable
[2022-02-13 21:20:07,075]{C:\Users\User\PycharmProjects\flask-shop\venv\lib\site-packages\flask\app.py:1890}
ERROR - Exception on /dashboard/products/90/edit [POST]
Traceback (most recent call last):
  File "C:\Users\User\PycharmProjects\flask-shop\venv\lib\site-packages\flask\app.py", line 2446, in wsgi_app
    response = self.full_dispatch_request()
  File "C:\Users\User\PycharmProjects\flask-shop\venv\lib\site-packages\flask\app.py", line 1951, in full_dispatch_request
    rv = self.handle_user_exception(e)
  File "C:\Users\User\PycharmProjects\flask-shop\venv\lib\site-packages\flask_restplus\api.py", line 584, in error_router
    return original_handler(e)
  File "C:\Users\User\PycharmProjects\flask-shop\venv\lib\site-packages\flask\app.py", line 1820, in handle_user_exception
    reraise(exc_type, exc_value, tb)
  File "C:\Users\User\PycharmProjects\flask-shop\venv\lib\site-packages\flask\_compat.py", line 39, in reraise
    raise value
  File "C:\Users\User\PycharmProjects\flask-shop\venv\lib\site-packages\flask\app.py", line 1949, in full_dispatch_request
    rv = self.dispatch_request()
  File "C:\Users\User\PycharmProjects\flask-shop\venv\lib\site-packages\flask\app.py", line 1935, in dispatch_request
    return self.view_functions[rule.endpoint](**req.view_args)
  File "C:\Users\User\PycharmProjects\flask-shop\flask-shop-master\flaskshop\dashboard\views\product.py", line 409, in product_manage
    product_type= product.product_type()
TypeError: 'ProductType' object is not callable
[2022-02-13 21:21:55,777]{C:\Users\User\PycharmProjects\flask-shop\venv\lib\site-packages\flask\app.py:1890}
ERROR - Exception on /dashboard/products/90/edit [POST]
Traceback (most recent call last):
  File "C:\Users\User\PycharmProjects\flask-shop\venv\lib\site-packages\flask\app.py", line 2446, in wsgi_app
    response = self.full_dispatch_request()
  File "C:\Users\User\PycharmProjects\flask-shop\venv\lib\site-packages\flask\app.py", line 1951, in full_dispatch_request
    rv = self.handle_user_exception(e)
  File "C:\Users\User\PycharmProjects\flask-shop\venv\lib\site-packages\flask_restplus\api.py", line 584, in error_router
    return original_handler(e)
  File "C:\Users\User\PycharmProjects\flask-shop\venv\lib\site-packages\flask\app.py", line 1820, in handle_user_exception
    reraise(exc_type, exc_value, tb)
  File "C:\Users\User\PycharmProjects\flask-shop\venv\lib\site-packages\flask\_compat.py", line 39, in reraise
    raise value
  File "C:\Users\User\PycharmProjects\flask-shop\venv\lib\site-packages\flask\app.py", line 1949, in full_dispatch_request
    rv = self.dispatch_request()
  File "C:\Users\User\PycharmProjects\flask-shop\venv\lib\site-packages\flask\app.py", line 1935, in dispatch_request
    return self.view_functions[rule.endpoint](**req.view_args)
  File "C:\Users\User\PycharmProjects\flask-shop\flask-shop-master\flaskshop\dashboard\views\product.py", line 411, in product_manage
    product = _save_product(product, form)
  File "C:\Users\User\PycharmProjects\flask-shop\flask-shop-master\flaskshop\dashboard\views\product.py", line 316, in _save_product
    product.update_attributes(form.attributes.data)
  File "C:\Users\User\PycharmProjects\flask-shop\flask-shop-master\flaskshop\product\models.py", line 223, in update_attributes
    attr_entries = [str(item.id) for item in self.product_type.product_attributes]
AttributeError: 'function' object has no attribute 'product_attributes'
[2022-02-13 21:24:11,921]{C:\Users\User\PycharmProjects\flask-shop\venv\lib\site-packages\flask\app.py:1890}
ERROR - Exception on /dashboard/products/68/edit [POST]
Traceback (most recent call last):
  File "C:\Users\User\PycharmProjects\flask-shop\venv\lib\site-packages\flask\app.py", line 2446, in wsgi_app
    response = self.full_dispatch_request()
  File "C:\Users\User\PycharmProjects\flask-shop\venv\lib\site-packages\flask\app.py", line 1951, in full_dispatch_request
    rv = self.handle_user_exception(e)
  File "C:\Users\User\PycharmProjects\flask-shop\venv\lib\site-packages\flask_restplus\api.py", line 584, in error_router
    return original_handler(e)
  File "C:\Users\User\PycharmProjects\flask-shop\venv\lib\site-packages\flask\app.py", line 1820, in handle_user_exception
    reraise(exc_type, exc_value, tb)
  File "C:\Users\User\PycharmProjects\flask-shop\venv\lib\site-packages\flask\_compat.py", line 39, in reraise
    raise value
  File "C:\Users\User\PycharmProjects\flask-shop\venv\lib\site-packages\flask\app.py", line 1949, in full_dispatch_request
    rv = self.dispatch_request()
  File "C:\Users\User\PycharmProjects\flask-shop\venv\lib\site-packages\flask\app.py", line 1935, in dispatch_request
    return self.view_functions[rule.endpoint](**req.view_args)
  File "C:\Users\User\PycharmProjects\flask-shop\flask-shop-master\flaskshop\dashboard\views\product.py", line 411, in product_manage
    product = _save_product(product, form)
  File "C:\Users\User\PycharmProjects\flask-shop\flask-shop-master\flaskshop\dashboard\views\product.py", line 316, in _save_product
    product.update_attributes(form.attributes.data)
  File "C:\Users\User\PycharmProjects\flask-shop\flask-shop-master\flaskshop\product\models.py", line 223, in update_attributes
    attr_entries = [str(item.id) for item in self.product_type.product_attributes]
AttributeError: 'function' object has no attribute 'product_attributes'
[2022-02-13 21:27:24,209]{C:\Users\User\PycharmProjects\flask-shop\venv\lib\site-packages\flask\app.py:1890}
ERROR - Exception on /dashboard/products/69/edit [POST]
Traceback (most recent call last):
  File "C:\Users\User\PycharmProjects\flask-shop\venv\lib\site-packages\flask\app.py", line 2446, in wsgi_app
    response = self.full_dispatch_request()
  File "C:\Users\User\PycharmProjects\flask-shop\venv\lib\site-packages\flask\app.py", line 1951, in full_dispatch_request
    rv = self.handle_user_exception(e)
  File "C:\Users\User\PycharmProjects\flask-shop\venv\lib\site-packages\flask_restplus\api.py", line 584, in error_router
    return original_handler(e)
  File "C:\Users\User\PycharmProjects\flask-shop\venv\lib\site-packages\flask\app.py", line 1820, in handle_user_exception
    reraise(exc_type, exc_value, tb)
  File "C:\Users\User\PycharmProjects\flask-shop\venv\lib\site-packages\flask\_compat.py", line 39, in reraise
    raise value
  File "C:\Users\User\PycharmProjects\flask-shop\venv\lib\site-packages\flask\app.py", line 1949, in full_dispatch_request
    rv = self.dispatch_request()
  File "C:\Users\User\PycharmProjects\flask-shop\venv\lib\site-packages\flask\app.py", line 1935, in dispatch_request
    return self.view_functions[rule.endpoint](**req.view_args)
  File "C:\Users\User\PycharmProjects\flask-shop\flask-shop-master\flaskshop\dashboard\views\product.py", line 411, in product_manage
    product = _save_product(product, form)
  File "C:\Users\User\PycharmProjects\flask-shop\flask-shop-master\flaskshop\dashboard\views\product.py", line 316, in _save_product
    product.update_attributes(form.attributes.data)
  File "C:\Users\User\PycharmProjects\flask-shop\flask-shop-master\flaskshop\product\models.py", line 223, in update_attributes
    attr_entries = [str(item.id) for item in self.product_type.product_attributes]
AttributeError: 'function' object has no attribute 'product_attributes'
[2022-02-13 21:30:40,482]{C:\Users\User\PycharmProjects\flask-shop\venv\lib\site-packages\flask\app.py:1890}
ERROR - Exception on /dashboard/products/62/edit [POST]
Traceback (most recent call last):
  File "C:\Users\User\PycharmProjects\flask-shop\venv\lib\site-packages\flask\app.py", line 2446, in wsgi_app
    response = self.full_dispatch_request()
  File "C:\Users\User\PycharmProjects\flask-shop\venv\lib\site-packages\flask\app.py", line 1951, in full_dispatch_request
    rv = self.handle_user_exception(e)
  File "C:\Users\User\PycharmProjects\flask-shop\venv\lib\site-packages\flask_restplus\api.py", line 584, in error_router
    return original_handler(e)
  File "C:\Users\User\PycharmProjects\flask-shop\venv\lib\site-packages\flask\app.py", line 1820, in handle_user_exception
    reraise(exc_type, exc_value, tb)
  File "C:\Users\User\PycharmProjects\flask-shop\venv\lib\site-packages\flask\_compat.py", line 39, in reraise
    raise value
  File "C:\Users\User\PycharmProjects\flask-shop\venv\lib\site-packages\flask\app.py", line 1949, in full_dispatch_request
    rv = self.dispatch_request()
  File "C:\Users\User\PycharmProjects\flask-shop\venv\lib\site-packages\flask\app.py", line 1935, in dispatch_request
    return self.view_functions[rule.endpoint](**req.view_args)
  File "C:\Users\User\PycharmProjects\flask-shop\flask-shop-master\flaskshop\dashboard\views\product.py", line 411, in product_manage
    product = _save_product(product, form)
  File "C:\Users\User\PycharmProjects\flask-shop\flask-shop-master\flaskshop\dashboard\views\product.py", line 316, in _save_product
    product.update_attributes(form.attributes.data)
  File "C:\Users\User\PycharmProjects\flask-shop\flask-shop-master\flaskshop\product\models.py", line 223, in update_attributes
    attr_entries = [str(item.id) for item in self.product_type.product_attributes]
AttributeError: 'function' object has no attribute 'product_attributes'
[2022-02-13 21:31:21,288]{C:\Users\User\PycharmProjects\flask-shop\venv\lib\site-packages\flask\app.py:1890}
ERROR - Exception on /dashboard/products/66/edit [POST]
Traceback (most recent call last):
  File "C:\Users\User\PycharmProjects\flask-shop\venv\lib\site-packages\flask\app.py", line 2446, in wsgi_app
    response = self.full_dispatch_request()
  File "C:\Users\User\PycharmProjects\flask-shop\venv\lib\site-packages\flask\app.py", line 1951, in full_dispatch_request
    rv = self.handle_user_exception(e)
  File "C:\Users\User\PycharmProjects\flask-shop\venv\lib\site-packages\flask_restplus\api.py", line 584, in error_router
    return original_handler(e)
  File "C:\Users\User\PycharmProjects\flask-shop\venv\lib\site-packages\flask\app.py", line 1820, in handle_user_exception
    reraise(exc_type, exc_value, tb)
  File "C:\Users\User\PycharmProjects\flask-shop\venv\lib\site-packages\flask\_compat.py", line 39, in reraise
    raise value
  File "C:\Users\User\PycharmProjects\flask-shop\venv\lib\site-packages\flask\app.py", line 1949, in full_dispatch_request
    rv = self.dispatch_request()
  File "C:\Users\User\PycharmProjects\flask-shop\venv\lib\site-packages\flask\app.py", line 1935, in dispatch_request
    return self.view_functions[rule.endpoint](**req.view_args)
  File "C:\Users\User\PycharmProjects\flask-shop\flask-shop-master\flaskshop\dashboard\views\product.py", line 430, in product_manage
    product.generate_variants()
  File "C:\Users\User\PycharmProjects\flask-shop\flask-shop-master\flaskshop\product\models.py", line 228, in generate_variants
    if not self.product_type.has_variants:
AttributeError: 'function' object has no attribute 'has_variants'
[2022-02-13 21:32:39,915]{C:\Users\User\PycharmProjects\flask-shop\venv\lib\site-packages\flask\app.py:1890}
ERROR - Exception on /dashboard/products/63/edit [POST]
Traceback (most recent call last):
  File "C:\Users\User\PycharmProjects\flask-shop\venv\lib\site-packages\flask\app.py", line 2446, in wsgi_app
    response = self.full_dispatch_request()
  File "C:\Users\User\PycharmProjects\flask-shop\venv\lib\site-packages\flask\app.py", line 1951, in full_dispatch_request
    rv = self.handle_user_exception(e)
  File "C:\Users\User\PycharmProjects\flask-shop\venv\lib\site-packages\flask_restplus\api.py", line 584, in error_router
    return original_handler(e)
  File "C:\Users\User\PycharmProjects\flask-shop\venv\lib\site-packages\flask\app.py", line 1820, in handle_user_exception
    reraise(exc_type, exc_value, tb)
  File "C:\Users\User\PycharmProjects\flask-shop\venv\lib\site-packages\flask\_compat.py", line 39, in reraise
    raise value
  File "C:\Users\User\PycharmProjects\flask-shop\venv\lib\site-packages\flask\app.py", line 1949, in full_dispatch_request
    rv = self.dispatch_request()
  File "C:\Users\User\PycharmProjects\flask-shop\venv\lib\site-packages\flask\app.py", line 1935, in dispatch_request
    return self.view_functions[rule.endpoint](**req.view_args)
  File "C:\Users\User\PycharmProjects\flask-shop\flask-shop-master\flaskshop\dashboard\views\product.py", line 430, in product_manage
    product.generate_variants()
  File "C:\Users\User\PycharmProjects\flask-shop\flask-shop-master\flaskshop\product\models.py", line 233, in generate_variants
    attr: attr.values for attr in self.product_type.variant_attributes
AttributeError: 'function' object has no attribute 'variant_attributes'
[2022-02-13 21:57:48,542]{C:\Users\User\PycharmProjects\flask-shop\venv\lib\site-packages\flask\app.py:1890}
ERROR - Exception on / [GET]
Traceback (most recent call last):
  File "C:\Users\User\PycharmProjects\flask-shop\venv\lib\site-packages\sqlalchemy\util\_collections.py", line 1020, in __call__
    return self.registry[key]
KeyError: <greenlet.greenlet object at 0x0000023A70DC23B0 (otid=0x0000023A70DD8580) current active started main>

During handling of the above exception, another exception occurred:

Traceback (most recent call last):
  File "C:\Users\User\PycharmProjects\flask-shop\venv\lib\site-packages\flask\app.py", line 2446, in wsgi_app
    response = self.full_dispatch_request()
  File "C:\Users\User\PycharmProjects\flask-shop\venv\lib\site-packages\flask\app.py", line 1951, in full_dispatch_request
    rv = self.handle_user_exception(e)
  File "C:\Users\User\PycharmProjects\flask-shop\venv\lib\site-packages\flask_restplus\api.py", line 584, in error_router
    return original_handler(e)
  File "C:\Users\User\PycharmProjects\flask-shop\venv\lib\site-packages\flask\app.py", line 1820, in handle_user_exception
    reraise(exc_type, exc_value, tb)
  File "C:\Users\User\PycharmProjects\flask-shop\venv\lib\site-packages\flask\_compat.py", line 39, in reraise
    raise value
  File "C:\Users\User\PycharmProjects\flask-shop\venv\lib\site-packages\flask\app.py", line 1949, in full_dispatch_request
    rv = self.dispatch_request()
  File "C:\Users\User\PycharmProjects\flask-shop\venv\lib\site-packages\flask\app.py", line 1935, in dispatch_request
    return self.view_functions[rule.endpoint](**req.view_args)
  File "C:\Users\User\PycharmProjects\flask-shop\flask-shop-master\flaskshop\public\views.py", line 26, in home
    products= Product.query.all()
  File "C:\Users\User\PycharmProjects\flask-shop\venv\lib\site-packages\flask_sqlalchemy\__init__.py", line 519, in __get__
    return type.query_class(mapper, session=self.sa.session())
  File "C:\Users\User\PycharmProjects\flask-shop\venv\lib\site-packages\sqlalchemy\orm\scoping.py", line 78, in __call__
    return self.registry()
  File "C:\Users\User\PycharmProjects\flask-shop\venv\lib\site-packages\sqlalchemy\util\_collections.py", line 1022, in __call__
    return self.registry.setdefault(key, self.createfunc())
  File "C:\Users\User\PycharmProjects\flask-shop\venv\lib\site-packages\sqlalchemy\orm\session.py", line 3309, in __call__
    return self.class_(**local_kw)
  File "C:\Users\User\PycharmProjects\flask-shop\venv\lib\site-packages\flask_sqlalchemy\__init__.py", line 138, in __init__
    bind = options.pop('bind', None) or db.engine
  File "C:\Users\User\PycharmProjects\flask-shop\venv\lib\site-packages\flask_sqlalchemy\__init__.py", line 937, in engine
    return self.get_engine()
  File "C:\Users\User\PycharmProjects\flask-shop\venv\lib\site-packages\flask_sqlalchemy\__init__.py", line 956, in get_engine
    return connector.get_engine()
  File "C:\Users\User\PycharmProjects\flask-shop\venv\lib\site-packages\flask_sqlalchemy\__init__.py", line 560, in get_engine
    options = self.get_options(sa_url, echo)
  File "C:\Users\User\PycharmProjects\flask-shop\venv\lib\site-packages\flask_sqlalchemy\__init__.py", line 575, in get_options
    self._sa.apply_driver_hacks(self._app, sa_url, options)
  File "C:\Users\User\PycharmProjects\flask-shop\flask-shop-master\flaskshop\extensions.py", line 147, in apply_driver_hacks
    return super().apply_driver_hacks(app, info, options)
  File "C:\Users\User\PycharmProjects\flask-shop\venv\lib\site-packages\flask_sqlalchemy\__init__.py", line 877, in apply_driver_hacks
    if sa_url.drivername.startswith('mysql'):
AttributeError: 'NoneType' object has no attribute 'drivername'
[2022-02-13 21:58:37,377]{C:\Users\User\PycharmProjects\flask-shop\venv\lib\site-packages\flask\app.py:1890}
ERROR - Exception on / [GET]
Traceback (most recent call last):
  File "C:\Users\User\PycharmProjects\flask-shop\venv\lib\site-packages\sqlalchemy\util\_collections.py", line 1020, in __call__
    return self.registry[key]
KeyError: <greenlet.greenlet object at 0x00000228AA1703B0 (otid=0x00000228AA187440) current active started main>

During handling of the above exception, another exception occurred:

Traceback (most recent call last):
  File "C:\Users\User\PycharmProjects\flask-shop\venv\lib\site-packages\flask\app.py", line 2446, in wsgi_app
    response = self.full_dispatch_request()
  File "C:\Users\User\PycharmProjects\flask-shop\venv\lib\site-packages\flask\app.py", line 1951, in full_dispatch_request
    rv = self.handle_user_exception(e)
  File "C:\Users\User\PycharmProjects\flask-shop\venv\lib\site-packages\flask_restplus\api.py", line 584, in error_router
    return original_handler(e)
  File "C:\Users\User\PycharmProjects\flask-shop\venv\lib\site-packages\flask\app.py", line 1820, in handle_user_exception
    reraise(exc_type, exc_value, tb)
  File "C:\Users\User\PycharmProjects\flask-shop\venv\lib\site-packages\flask\_compat.py", line 39, in reraise
    raise value
  File "C:\Users\User\PycharmProjects\flask-shop\venv\lib\site-packages\flask\app.py", line 1949, in full_dispatch_request
    rv = self.dispatch_request()
  File "C:\Users\User\PycharmProjects\flask-shop\venv\lib\site-packages\flask\app.py", line 1935, in dispatch_request
    return self.view_functions[rule.endpoint](**req.view_args)
  File "C:\Users\User\PycharmProjects\flask-shop\flask-shop-master\flaskshop\public\views.py", line 26, in home
    products= Product.query.all()
  File "C:\Users\User\PycharmProjects\flask-shop\venv\lib\site-packages\flask_sqlalchemy\__init__.py", line 519, in __get__
    return type.query_class(mapper, session=self.sa.session())
  File "C:\Users\User\PycharmProjects\flask-shop\venv\lib\site-packages\sqlalchemy\orm\scoping.py", line 78, in __call__
    return self.registry()
  File "C:\Users\User\PycharmProjects\flask-shop\venv\lib\site-packages\sqlalchemy\util\_collections.py", line 1022, in __call__
    return self.registry.setdefault(key, self.createfunc())
  File "C:\Users\User\PycharmProjects\flask-shop\venv\lib\site-packages\sqlalchemy\orm\session.py", line 3309, in __call__
    return self.class_(**local_kw)
  File "C:\Users\User\PycharmProjects\flask-shop\venv\lib\site-packages\flask_sqlalchemy\__init__.py", line 138, in __init__
    bind = options.pop('bind', None) or db.engine
  File "C:\Users\User\PycharmProjects\flask-shop\venv\lib\site-packages\flask_sqlalchemy\__init__.py", line 937, in engine
    return self.get_engine()
  File "C:\Users\User\PycharmProjects\flask-shop\venv\lib\site-packages\flask_sqlalchemy\__init__.py", line 956, in get_engine
    return connector.get_engine()
  File "C:\Users\User\PycharmProjects\flask-shop\venv\lib\site-packages\flask_sqlalchemy\__init__.py", line 560, in get_engine
    options = self.get_options(sa_url, echo)
  File "C:\Users\User\PycharmProjects\flask-shop\venv\lib\site-packages\flask_sqlalchemy\__init__.py", line 575, in get_options
    self._sa.apply_driver_hacks(self._app, sa_url, options)
  File "C:\Users\User\PycharmProjects\flask-shop\flask-shop-master\flaskshop\extensions.py", line 147, in apply_driver_hacks
    return super().apply_driver_hacks(app, info, options)
  File "C:\Users\User\PycharmProjects\flask-shop\venv\lib\site-packages\flask_sqlalchemy\__init__.py", line 877, in apply_driver_hacks
    if sa_url.drivername.startswith('mysql'):
AttributeError: 'NoneType' object has no attribute 'drivername'
[2022-02-13 21:59:50,743]{C:\Users\User\PycharmProjects\flask-shop\venv\lib\site-packages\flask\app.py:1890}
ERROR - Exception on / [GET]
Traceback (most recent call last):
  File "C:\Users\User\PycharmProjects\flask-shop\venv\lib\site-packages\sqlalchemy\engine\base.py", line 2336, in _wrap_pool_connect
    return fn()
  File "C:\Users\User\PycharmProjects\flask-shop\venv\lib\site-packages\sqlalchemy\pool\base.py", line 364, in connect
    return _ConnectionFairy._checkout(self)
  File "C:\Users\User\PycharmProjects\flask-shop\venv\lib\site-packages\sqlalchemy\pool\base.py", line 778, in _checkout
    fairy = _ConnectionRecord.checkout(pool)
  File "C:\Users\User\PycharmProjects\flask-shop\venv\lib\site-packages\sqlalchemy\pool\base.py", line 495, in checkout
    rec = pool._do_get()
  File "C:\Users\User\PycharmProjects\flask-shop\venv\lib\site-packages\sqlalchemy\pool\impl.py", line 140, in _do_get
    self._dec_overflow()
  File "C:\Users\User\PycharmProjects\flask-shop\venv\lib\site-packages\sqlalchemy\util\langhelpers.py", line 68, in __exit__
    compat.raise_(
  File "C:\Users\User\PycharmProjects\flask-shop\venv\lib\site-packages\sqlalchemy\util\compat.py", line 182, in raise_
    raise exception
  File "C:\Users\User\PycharmProjects\flask-shop\venv\lib\site-packages\sqlalchemy\pool\impl.py", line 137, in _do_get
    return self._create_connection()
  File "C:\Users\User\PycharmProjects\flask-shop\venv\lib\site-packages\sqlalchemy\pool\base.py", line 309, in _create_connection
    return _ConnectionRecord(self)
  File "C:\Users\User\PycharmProjects\flask-shop\venv\lib\site-packages\sqlalchemy\pool\base.py", line 440, in __init__
    self.__connect(first_connect_check=True)
  File "C:\Users\User\PycharmProjects\flask-shop\venv\lib\site-packages\sqlalchemy\pool\base.py", line 661, in __connect
    pool.logger.debug("Error on connect(): %s", e)
  File "C:\Users\User\PycharmProjects\flask-shop\venv\lib\site-packages\sqlalchemy\util\langhelpers.py", line 68, in __exit__
    compat.raise_(
  File "C:\Users\User\PycharmProjects\flask-shop\venv\lib\site-packages\sqlalchemy\util\compat.py", line 182, in raise_
    raise exception
  File "C:\Users\User\PycharmProjects\flask-shop\venv\lib\site-packages\sqlalchemy\pool\base.py", line 656, in __connect
    connection = pool._invoke_creator(self)
  File "C:\Users\User\PycharmProjects\flask-shop\venv\lib\site-packages\sqlalchemy\engine\strategies.py", line 114, in connect
    return dialect.connect(*cargs, **cparams)
  File "C:\Users\User\PycharmProjects\flask-shop\venv\lib\site-packages\sqlalchemy\engine\default.py", line 508, in connect
    return self.dbapi.connect(*cargs, **cparams)
  File "C:\Users\User\PycharmProjects\flask-shop\venv\lib\site-packages\MySQLdb\__init__.py", line 130, in Connect
    return Connection(*args, **kwargs)
  File "C:\Users\User\PycharmProjects\flask-shop\venv\lib\site-packages\MySQLdb\connections.py", line 185, in __init__
    super().__init__(*args, **kwargs2)
MySQLdb._exceptions.OperationalError: (1049, "Unknown database 'db3'")

The above exception was the direct cause of the following exception:

Traceback (most recent call last):
  File "C:\Users\User\PycharmProjects\flask-shop\venv\lib\site-packages\flask\app.py", line 2446, in wsgi_app
    response = self.full_dispatch_request()
  File "C:\Users\User\PycharmProjects\flask-shop\venv\lib\site-packages\flask\app.py", line 1951, in full_dispatch_request
    rv = self.handle_user_exception(e)
  File "C:\Users\User\PycharmProjects\flask-shop\venv\lib\site-packages\flask_restplus\api.py", line 584, in error_router
    return original_handler(e)
  File "C:\Users\User\PycharmProjects\flask-shop\venv\lib\site-packages\flask\app.py", line 1820, in handle_user_exception
    reraise(exc_type, exc_value, tb)
  File "C:\Users\User\PycharmProjects\flask-shop\venv\lib\site-packages\flask\_compat.py", line 39, in reraise
    raise value
  File "C:\Users\User\PycharmProjects\flask-shop\venv\lib\site-packages\flask\app.py", line 1949, in full_dispatch_request
    rv = self.dispatch_request()
  File "C:\Users\User\PycharmProjects\flask-shop\venv\lib\site-packages\flask\app.py", line 1935, in dispatch_request
    return self.view_functions[rule.endpoint](**req.view_args)
  File "C:\Users\User\PycharmProjects\flask-shop\flask-shop-master\flaskshop\public\views.py", line 26, in home
    products= Product.query.all()
  File "C:\Users\User\PycharmProjects\flask-shop\venv\lib\site-packages\sqlalchemy\orm\query.py", line 3373, in all
    return list(self)
  File "C:\Users\User\PycharmProjects\flask-shop\venv\lib\site-packages\sqlalchemy\orm\query.py", line 3535, in __iter__
    return self._execute_and_instances(context)
  File "C:\Users\User\PycharmProjects\flask-shop\venv\lib\site-packages\sqlalchemy\orm\query.py", line 3556, in _execute_and_instances
    conn = self._get_bind_args(
  File "C:\Users\User\PycharmProjects\flask-shop\venv\lib\site-packages\sqlalchemy\orm\query.py", line 3571, in _get_bind_args
    return fn(
  File "C:\Users\User\PycharmProjects\flask-shop\venv\lib\site-packages\sqlalchemy\orm\query.py", line 3550, in _connection_from_session
    conn = self.session.connection(**kw)
  File "C:\Users\User\PycharmProjects\flask-shop\venv\lib\site-packages\sqlalchemy\orm\session.py", line 1142, in connection
    return self._connection_for_bind(
  File "C:\Users\User\PycharmProjects\flask-shop\venv\lib\site-packages\sqlalchemy\orm\session.py", line 1150, in _connection_for_bind
    return self.transaction._connection_for_bind(
  File "C:\Users\User\PycharmProjects\flask-shop\venv\lib\site-packages\sqlalchemy\orm\session.py", line 433, in _connection_for_bind
    conn = bind._contextual_connect()
  File "C:\Users\User\PycharmProjects\flask-shop\venv\lib\site-packages\sqlalchemy\engine\base.py", line 2302, in _contextual_connect
    self._wrap_pool_connect(self.pool.connect, None),
  File "C:\Users\User\PycharmProjects\flask-shop\venv\lib\site-packages\sqlalchemy\engine\base.py", line 2339, in _wrap_pool_connect
    Connection._handle_dbapi_exception_noconnection(
  File "C:\Users\User\PycharmProjects\flask-shop\venv\lib\site-packages\sqlalchemy\engine\base.py", line 1583, in _handle_dbapi_exception_noconnection
    util.raise_(
  File "C:\Users\User\PycharmProjects\flask-shop\venv\lib\site-packages\sqlalchemy\util\compat.py", line 182, in raise_
    raise exception
  File "C:\Users\User\PycharmProjects\flask-shop\venv\lib\site-packages\sqlalchemy\engine\base.py", line 2336, in _wrap_pool_connect
    return fn()
  File "C:\Users\User\PycharmProjects\flask-shop\venv\lib\site-packages\sqlalchemy\pool\base.py", line 364, in connect
    return _ConnectionFairy._checkout(self)
  File "C:\Users\User\PycharmProjects\flask-shop\venv\lib\site-packages\sqlalchemy\pool\base.py", line 778, in _checkout
    fairy = _ConnectionRecord.checkout(pool)
  File "C:\Users\User\PycharmProjects\flask-shop\venv\lib\site-packages\sqlalchemy\pool\base.py", line 495, in checkout
    rec = pool._do_get()
  File "C:\Users\User\PycharmProjects\flask-shop\venv\lib\site-packages\sqlalchemy\pool\impl.py", line 140, in _do_get
    self._dec_overflow()
  File "C:\Users\User\PycharmProjects\flask-shop\venv\lib\site-packages\sqlalchemy\util\langhelpers.py", line 68, in __exit__
    compat.raise_(
  File "C:\Users\User\PycharmProjects\flask-shop\venv\lib\site-packages\sqlalchemy\util\compat.py", line 182, in raise_
    raise exception
  File "C:\Users\User\PycharmProjects\flask-shop\venv\lib\site-packages\sqlalchemy\pool\impl.py", line 137, in _do_get
    return self._create_connection()
  File "C:\Users\User\PycharmProjects\flask-shop\venv\lib\site-packages\sqlalchemy\pool\base.py", line 309, in _create_connection
    return _ConnectionRecord(self)
  File "C:\Users\User\PycharmProjects\flask-shop\venv\lib\site-packages\sqlalchemy\pool\base.py", line 440, in __init__
    self.__connect(first_connect_check=True)
  File "C:\Users\User\PycharmProjects\flask-shop\venv\lib\site-packages\sqlalchemy\pool\base.py", line 661, in __connect
    pool.logger.debug("Error on connect(): %s", e)
  File "C:\Users\User\PycharmProjects\flask-shop\venv\lib\site-packages\sqlalchemy\util\langhelpers.py", line 68, in __exit__
    compat.raise_(
  File "C:\Users\User\PycharmProjects\flask-shop\venv\lib\site-packages\sqlalchemy\util\compat.py", line 182, in raise_
    raise exception
  File "C:\Users\User\PycharmProjects\flask-shop\venv\lib\site-packages\sqlalchemy\pool\base.py", line 656, in __connect
    connection = pool._invoke_creator(self)
  File "C:\Users\User\PycharmProjects\flask-shop\venv\lib\site-packages\sqlalchemy\engine\strategies.py", line 114, in connect
    return dialect.connect(*cargs, **cparams)
  File "C:\Users\User\PycharmProjects\flask-shop\venv\lib\site-packages\sqlalchemy\engine\default.py", line 508, in connect
    return self.dbapi.connect(*cargs, **cparams)
  File "C:\Users\User\PycharmProjects\flask-shop\venv\lib\site-packages\MySQLdb\__init__.py", line 130, in Connect
    return Connection(*args, **kwargs)
  File "C:\Users\User\PycharmProjects\flask-shop\venv\lib\site-packages\MySQLdb\connections.py", line 185, in __init__
    super().__init__(*args, **kwargs2)
sqlalchemy.exc.OperationalError: (MySQLdb._exceptions.OperationalError) (1049, "Unknown database 'db3'")
(Background on this error at: http://sqlalche.me/e/13/e3q8)
[2022-02-13 22:00:28,911]{C:\Users\User\PycharmProjects\flask-shop\venv\lib\site-packages\flask\app.py:1890}
ERROR - Exception on / [GET]
Traceback (most recent call last):
  File "C:\Users\User\PycharmProjects\flask-shop\venv\lib\site-packages\flask\app.py", line 2446, in wsgi_app
    response = self.full_dispatch_request()
  File "C:\Users\User\PycharmProjects\flask-shop\venv\lib\site-packages\flask\app.py", line 1951, in full_dispatch_request
    rv = self.handle_user_exception(e)
  File "C:\Users\User\PycharmProjects\flask-shop\venv\lib\site-packages\flask_restplus\api.py", line 584, in error_router
    return original_handler(e)
  File "C:\Users\User\PycharmProjects\flask-shop\venv\lib\site-packages\flask\app.py", line 1820, in handle_user_exception
    reraise(exc_type, exc_value, tb)
  File "C:\Users\User\PycharmProjects\flask-shop\venv\lib\site-packages\flask\_compat.py", line 39, in reraise
    raise value
  File "C:\Users\User\PycharmProjects\flask-shop\venv\lib\site-packages\flask\app.py", line 1949, in full_dispatch_request
    rv = self.dispatch_request()
  File "C:\Users\User\PycharmProjects\flask-shop\venv\lib\site-packages\flask\app.py", line 1935, in dispatch_request
    return self.view_functions[rule.endpoint](**req.view_args)
  File "C:\Users\User\PycharmProjects\flask-shop\flask-shop-master\flaskshop\public\views.py", line 30, in home
    return render_template("public/shopHomePage.html", products= products,categories=categories)
  File "C:\Users\User\PycharmProjects\flask-shop\venv\lib\site-packages\flask\templating.py", line 137, in render_template
    return _render(
  File "C:\Users\User\PycharmProjects\flask-shop\venv\lib\site-packages\flask\templating.py", line 120, in _render
    rv = template.render(context)
  File "C:\Users\User\PycharmProjects\flask-shop\venv\lib\site-packages\jinja2\environment.py", line 1090, in render
    self.environment.handle_exception()
  File "C:\Users\User\PycharmProjects\flask-shop\venv\lib\site-packages\jinja2\environment.py", line 832, in handle_exception
    reraise(*rewrite_traceback_stack(source=source))
  File "C:\Users\User\PycharmProjects\flask-shop\venv\lib\site-packages\jinja2\_compat.py", line 28, in reraise
    raise value.with_traceback(tb)
  File "C:\Users\User\PycharmProjects\flask-shop\flask-shop-master\flaskshop\templates\public\shopHomePage.html", line 1, in top-level template code
    {% extends "base.html" %}
  File "C:\Users\User\PycharmProjects\flask-shop\flask-shop-master\flaskshop\templates\base.html", line 109, in top-level template code
    <a href= "{{ item.get_absolute_url()}}" class="single-cat-item">
  File "C:\Users\User\PycharmProjects\flask-shop\flask-shop-master\flaskshop\product\models.py", line 340, in get_absolute_url
    url=url_for("product.show_single", id=self.id)
  File "C:\Users\User\PycharmProjects\flask-shop\venv\lib\site-packages\flask\helpers.py", line 370, in url_for
    return appctx.app.handle_url_build_error(error, endpoint, values)
  File "C:\Users\User\PycharmProjects\flask-shop\venv\lib\site-packages\flask\app.py", line 2215, in handle_url_build_error
    reraise(exc_type, exc_value, tb)
  File "C:\Users\User\PycharmProjects\flask-shop\venv\lib\site-packages\flask\_compat.py", line 39, in reraise
    raise value
  File "C:\Users\User\PycharmProjects\flask-shop\venv\lib\site-packages\flask\helpers.py", line 357, in url_for
    rv = url_adapter.build(
  File "C:\Users\User\PycharmProjects\flask-shop\venv\lib\site-packages\werkzeug\routing.py", line 2020, in build
    raise BuildError(endpoint, values, method, self)
werkzeug.routing.BuildError: Could not build url for endpoint 'product.show_single' with values ['id']. Did you mean 'product.show_a_single_product' instead?
[2022-02-13 22:01:36,082]{C:\Users\User\PycharmProjects\flask-shop\venv\lib\site-packages\flask\app.py:1890}
ERROR - Exception on / [GET]
Traceback (most recent call last):
  File "C:\Users\User\PycharmProjects\flask-shop\venv\lib\site-packages\flask\app.py", line 2446, in wsgi_app
    response = self.full_dispatch_request()
  File "C:\Users\User\PycharmProjects\flask-shop\venv\lib\site-packages\flask\app.py", line 1951, in full_dispatch_request
    rv = self.handle_user_exception(e)
  File "C:\Users\User\PycharmProjects\flask-shop\venv\lib\site-packages\flask_restplus\api.py", line 584, in error_router
    return original_handler(e)
  File "C:\Users\User\PycharmProjects\flask-shop\venv\lib\site-packages\flask\app.py", line 1820, in handle_user_exception
    reraise(exc_type, exc_value, tb)
  File "C:\Users\User\PycharmProjects\flask-shop\venv\lib\site-packages\flask\_compat.py", line 39, in reraise
    raise value
  File "C:\Users\User\PycharmProjects\flask-shop\venv\lib\site-packages\flask\app.py", line 1949, in full_dispatch_request
    rv = self.dispatch_request()
  File "C:\Users\User\PycharmProjects\flask-shop\venv\lib\site-packages\flask\app.py", line 1935, in dispatch_request
    return self.view_functions[rule.endpoint](**req.view_args)
  File "C:\Users\User\PycharmProjects\flask-shop\flask-shop-master\flaskshop\public\views.py", line 30, in home
    return render_template("public/shopHomePage.html", products= products,categories=categories)
  File "C:\Users\User\PycharmProjects\flask-shop\venv\lib\site-packages\flask\templating.py", line 137, in render_template
    return _render(
  File "C:\Users\User\PycharmProjects\flask-shop\venv\lib\site-packages\flask\templating.py", line 120, in _render
    rv = template.render(context)
  File "C:\Users\User\PycharmProjects\flask-shop\venv\lib\site-packages\jinja2\environment.py", line 1090, in render
    self.environment.handle_exception()
  File "C:\Users\User\PycharmProjects\flask-shop\venv\lib\site-packages\jinja2\environment.py", line 832, in handle_exception
    reraise(*rewrite_traceback_stack(source=source))
  File "C:\Users\User\PycharmProjects\flask-shop\venv\lib\site-packages\jinja2\_compat.py", line 28, in reraise
    raise value.with_traceback(tb)
  File "C:\Users\User\PycharmProjects\flask-shop\flask-shop-master\flaskshop\templates\public\shopHomePage.html", line 1, in top-level template code
    {% extends "base.html" %}
  File "C:\Users\User\PycharmProjects\flask-shop\flask-shop-master\flaskshop\templates\base.html", line 109, in top-level template code
    <a href= "{{ item.get_absolute_url()}}" class="single-cat-item">
  File "C:\Users\User\PycharmProjects\flask-shop\flask-shop-master\flaskshop\product\models.py", line 340, in get_absolute_url
    url=url_for("product.show_single", id=self.id)
  File "C:\Users\User\PycharmProjects\flask-shop\venv\lib\site-packages\flask\helpers.py", line 370, in url_for
    return appctx.app.handle_url_build_error(error, endpoint, values)
  File "C:\Users\User\PycharmProjects\flask-shop\venv\lib\site-packages\flask\app.py", line 2215, in handle_url_build_error
    reraise(exc_type, exc_value, tb)
  File "C:\Users\User\PycharmProjects\flask-shop\venv\lib\site-packages\flask\_compat.py", line 39, in reraise
    raise value
  File "C:\Users\User\PycharmProjects\flask-shop\venv\lib\site-packages\flask\helpers.py", line 357, in url_for
    rv = url_adapter.build(
  File "C:\Users\User\PycharmProjects\flask-shop\venv\lib\site-packages\werkzeug\routing.py", line 2020, in build
    raise BuildError(endpoint, values, method, self)
werkzeug.routing.BuildError: Could not build url for endpoint 'product.show_single' with values ['id']. Did you mean 'product.show_a_single_product' instead?
[2022-02-13 22:02:47,109]{C:\Users\User\PycharmProjects\flask-shop\venv\lib\site-packages\flask\app.py:1890}
ERROR - Exception on / [GET]
Traceback (most recent call last):
  File "C:\Users\User\PycharmProjects\flask-shop\venv\lib\site-packages\flask\app.py", line 2446, in wsgi_app
    response = self.full_dispatch_request()
  File "C:\Users\User\PycharmProjects\flask-shop\venv\lib\site-packages\flask\app.py", line 1951, in full_dispatch_request
    rv = self.handle_user_exception(e)
  File "C:\Users\User\PycharmProjects\flask-shop\venv\lib\site-packages\flask_restplus\api.py", line 584, in error_router
    return original_handler(e)
  File "C:\Users\User\PycharmProjects\flask-shop\venv\lib\site-packages\flask\app.py", line 1820, in handle_user_exception
    reraise(exc_type, exc_value, tb)
  File "C:\Users\User\PycharmProjects\flask-shop\venv\lib\site-packages\flask\_compat.py", line 39, in reraise
    raise value
  File "C:\Users\User\PycharmProjects\flask-shop\venv\lib\site-packages\flask\app.py", line 1949, in full_dispatch_request
    rv = self.dispatch_request()
  File "C:\Users\User\PycharmProjects\flask-shop\venv\lib\site-packages\flask\app.py", line 1935, in dispatch_request
    return self.view_functions[rule.endpoint](**req.view_args)
  File "C:\Users\User\PycharmProjects\flask-shop\flask-shop-master\flaskshop\public\views.py", line 30, in home
    return render_template("public/shopHomePage.html", products= products,categories=categories)
  File "C:\Users\User\PycharmProjects\flask-shop\venv\lib\site-packages\flask\templating.py", line 137, in render_template
    return _render(
  File "C:\Users\User\PycharmProjects\flask-shop\venv\lib\site-packages\flask\templating.py", line 120, in _render
    rv = template.render(context)
  File "C:\Users\User\PycharmProjects\flask-shop\venv\lib\site-packages\jinja2\environment.py", line 1090, in render
    self.environment.handle_exception()
  File "C:\Users\User\PycharmProjects\flask-shop\venv\lib\site-packages\jinja2\environment.py", line 832, in handle_exception
    reraise(*rewrite_traceback_stack(source=source))
  File "C:\Users\User\PycharmProjects\flask-shop\venv\lib\site-packages\jinja2\_compat.py", line 28, in reraise
    raise value.with_traceback(tb)
  File "C:\Users\User\PycharmProjects\flask-shop\flask-shop-master\flaskshop\templates\public\shopHomePage.html", line 1, in top-level template code
    {% extends "base.html" %}
  File "C:\Users\User\PycharmProjects\flask-shop\flask-shop-master\flaskshop\templates\base.html", line 109, in top-level template code
    <a href= "{{ item.get_absolute_url()}}" class="single-cat-item">
  File "C:\Users\User\PycharmProjects\flask-shop\flask-shop-master\flaskshop\product\models.py", line 340, in get_absolute_url
    url=url_for("product.show_single", id=self.id)
  File "C:\Users\User\PycharmProjects\flask-shop\venv\lib\site-packages\flask\helpers.py", line 370, in url_for
    return appctx.app.handle_url_build_error(error, endpoint, values)
  File "C:\Users\User\PycharmProjects\flask-shop\venv\lib\site-packages\flask\app.py", line 2215, in handle_url_build_error
    reraise(exc_type, exc_value, tb)
  File "C:\Users\User\PycharmProjects\flask-shop\venv\lib\site-packages\flask\_compat.py", line 39, in reraise
    raise value
  File "C:\Users\User\PycharmProjects\flask-shop\venv\lib\site-packages\flask\helpers.py", line 357, in url_for
    rv = url_adapter.build(
  File "C:\Users\User\PycharmProjects\flask-shop\venv\lib\site-packages\werkzeug\routing.py", line 2020, in build
    raise BuildError(endpoint, values, method, self)
werkzeug.routing.BuildError: Could not build url for endpoint 'product.show_single' with values ['id']. Did you mean 'product.show_a_single_product' instead?
[2022-02-13 22:05:22,158]{C:\Users\User\PycharmProjects\flask-shop\venv\lib\site-packages\flask\app.py:1890}
ERROR - Exception on / [GET]
Traceback (most recent call last):
  File "C:\Users\User\PycharmProjects\flask-shop\venv\lib\site-packages\flask\app.py", line 2446, in wsgi_app
    response = self.full_dispatch_request()
  File "C:\Users\User\PycharmProjects\flask-shop\venv\lib\site-packages\flask\app.py", line 1951, in full_dispatch_request
    rv = self.handle_user_exception(e)
  File "C:\Users\User\PycharmProjects\flask-shop\venv\lib\site-packages\flask_restplus\api.py", line 584, in error_router
    return original_handler(e)
  File "C:\Users\User\PycharmProjects\flask-shop\venv\lib\site-packages\flask\app.py", line 1820, in handle_user_exception
    reraise(exc_type, exc_value, tb)
  File "C:\Users\User\PycharmProjects\flask-shop\venv\lib\site-packages\flask\_compat.py", line 39, in reraise
    raise value
  File "C:\Users\User\PycharmProjects\flask-shop\venv\lib\site-packages\flask\app.py", line 1949, in full_dispatch_request
    rv = self.dispatch_request()
  File "C:\Users\User\PycharmProjects\flask-shop\venv\lib\site-packages\flask\app.py", line 1935, in dispatch_request
    return self.view_functions[rule.endpoint](**req.view_args)
  File "C:\Users\User\PycharmProjects\flask-shop\flask-shop-master\flaskshop\public\views.py", line 30, in home
    return render_template("public/shopHomePage.html", products= products,categories=categories)
  File "C:\Users\User\PycharmProjects\flask-shop\venv\lib\site-packages\flask\templating.py", line 137, in render_template
    return _render(
  File "C:\Users\User\PycharmProjects\flask-shop\venv\lib\site-packages\flask\templating.py", line 120, in _render
    rv = template.render(context)
  File "C:\Users\User\PycharmProjects\flask-shop\venv\lib\site-packages\jinja2\environment.py", line 1090, in render
    self.environment.handle_exception()
  File "C:\Users\User\PycharmProjects\flask-shop\venv\lib\site-packages\jinja2\environment.py", line 832, in handle_exception
    reraise(*rewrite_traceback_stack(source=source))
  File "C:\Users\User\PycharmProjects\flask-shop\venv\lib\site-packages\jinja2\_compat.py", line 28, in reraise
    raise value.with_traceback(tb)
  File "C:\Users\User\PycharmProjects\flask-shop\flask-shop-master\flaskshop\templates\public\shopHomePage.html", line 1, in top-level template code
    {% extends "base.html" %}
  File "C:\Users\User\PycharmProjects\flask-shop\flask-shop-master\flaskshop\templates\base.html", line 109, in top-level template code
    <a href= "{{ item.get_absolute_url()}}" class="single-cat-item">
  File "C:\Users\User\PycharmProjects\flask-shop\flask-shop-master\flaskshop\product\models.py", line 340, in get_absolute_url
    url=url_for("product.show_single", id=self.id)
  File "C:\Users\User\PycharmProjects\flask-shop\venv\lib\site-packages\flask\helpers.py", line 370, in url_for
    return appctx.app.handle_url_build_error(error, endpoint, values)
  File "C:\Users\User\PycharmProjects\flask-shop\venv\lib\site-packages\flask\app.py", line 2215, in handle_url_build_error
    reraise(exc_type, exc_value, tb)
  File "C:\Users\User\PycharmProjects\flask-shop\venv\lib\site-packages\flask\_compat.py", line 39, in reraise
    raise value
  File "C:\Users\User\PycharmProjects\flask-shop\venv\lib\site-packages\flask\helpers.py", line 357, in url_for
    rv = url_adapter.build(
  File "C:\Users\User\PycharmProjects\flask-shop\venv\lib\site-packages\werkzeug\routing.py", line 2020, in build
    raise BuildError(endpoint, values, method, self)
werkzeug.routing.BuildError: Could not build url for endpoint 'product.show_single' with values ['id']. Did you mean 'product.show_a_single_product' instead?
[2022-02-13 22:06:29,873]{C:\Users\User\PycharmProjects\flask-shop\venv\lib\site-packages\flask\app.py:1890}
ERROR - Exception on / [GET]
Traceback (most recent call last):
  File "C:\Users\User\PycharmProjects\flask-shop\venv\lib\site-packages\flask\app.py", line 2446, in wsgi_app
    response = self.full_dispatch_request()
  File "C:\Users\User\PycharmProjects\flask-shop\venv\lib\site-packages\flask\app.py", line 1951, in full_dispatch_request
    rv = self.handle_user_exception(e)
  File "C:\Users\User\PycharmProjects\flask-shop\venv\lib\site-packages\flask_restplus\api.py", line 584, in error_router
    return original_handler(e)
  File "C:\Users\User\PycharmProjects\flask-shop\venv\lib\site-packages\flask\app.py", line 1820, in handle_user_exception
    reraise(exc_type, exc_value, tb)
  File "C:\Users\User\PycharmProjects\flask-shop\venv\lib\site-packages\flask\_compat.py", line 39, in reraise
    raise value
  File "C:\Users\User\PycharmProjects\flask-shop\venv\lib\site-packages\flask\app.py", line 1949, in full_dispatch_request
    rv = self.dispatch_request()
  File "C:\Users\User\PycharmProjects\flask-shop\venv\lib\site-packages\flask\app.py", line 1935, in dispatch_request
    return self.view_functions[rule.endpoint](**req.view_args)
  File "C:\Users\User\PycharmProjects\flask-shop\flask-shop-master\flaskshop\public\views.py", line 30, in home
    return render_template("public/shopHomePage.html", products= products,categories=categories)
  File "C:\Users\User\PycharmProjects\flask-shop\venv\lib\site-packages\flask\templating.py", line 137, in render_template
    return _render(
  File "C:\Users\User\PycharmProjects\flask-shop\venv\lib\site-packages\flask\templating.py", line 120, in _render
    rv = template.render(context)
  File "C:\Users\User\PycharmProjects\flask-shop\venv\lib\site-packages\jinja2\environment.py", line 1090, in render
    self.environment.handle_exception()
  File "C:\Users\User\PycharmProjects\flask-shop\venv\lib\site-packages\jinja2\environment.py", line 832, in handle_exception
    reraise(*rewrite_traceback_stack(source=source))
  File "C:\Users\User\PycharmProjects\flask-shop\venv\lib\site-packages\jinja2\_compat.py", line 28, in reraise
    raise value.with_traceback(tb)
  File "C:\Users\User\PycharmProjects\flask-shop\flask-shop-master\flaskshop\templates\public\shopHomePage.html", line 1, in top-level template code
    {% extends "base.html" %}
  File "C:\Users\User\PycharmProjects\flask-shop\flask-shop-master\flaskshop\templates\base.html", line 109, in top-level template code
    <a href= "{{ item.get_absolute_url()}}" class="single-cat-item">
  File "C:\Users\User\PycharmProjects\flask-shop\flask-shop-master\flaskshop\product\models.py", line 340, in get_absolute_url
    url=url_for("product.show_single", id=self.id)
  File "C:\Users\User\PycharmProjects\flask-shop\venv\lib\site-packages\flask\helpers.py", line 370, in url_for
    return appctx.app.handle_url_build_error(error, endpoint, values)
  File "C:\Users\User\PycharmProjects\flask-shop\venv\lib\site-packages\flask\app.py", line 2215, in handle_url_build_error
    reraise(exc_type, exc_value, tb)
  File "C:\Users\User\PycharmProjects\flask-shop\venv\lib\site-packages\flask\_compat.py", line 39, in reraise
    raise value
  File "C:\Users\User\PycharmProjects\flask-shop\venv\lib\site-packages\flask\helpers.py", line 357, in url_for
    rv = url_adapter.build(
  File "C:\Users\User\PycharmProjects\flask-shop\venv\lib\site-packages\werkzeug\routing.py", line 2020, in build
    raise BuildError(endpoint, values, method, self)
werkzeug.routing.BuildError: Could not build url for endpoint 'product.show_single' with values ['id']. Did you mean 'product.show_a_single_product' instead?
[2022-02-13 22:07:49,768]{C:\Users\User\PycharmProjects\flask-shop\venv\lib\site-packages\flask\app.py:1890}
ERROR - Exception on / [GET]
Traceback (most recent call last):
  File "C:\Users\User\PycharmProjects\flask-shop\venv\lib\site-packages\flask\app.py", line 2446, in wsgi_app
    response = self.full_dispatch_request()
  File "C:\Users\User\PycharmProjects\flask-shop\venv\lib\site-packages\flask\app.py", line 1951, in full_dispatch_request
    rv = self.handle_user_exception(e)
  File "C:\Users\User\PycharmProjects\flask-shop\venv\lib\site-packages\flask_restplus\api.py", line 584, in error_router
    return original_handler(e)
  File "C:\Users\User\PycharmProjects\flask-shop\venv\lib\site-packages\flask\app.py", line 1820, in handle_user_exception
    reraise(exc_type, exc_value, tb)
  File "C:\Users\User\PycharmProjects\flask-shop\venv\lib\site-packages\flask\_compat.py", line 39, in reraise
    raise value
  File "C:\Users\User\PycharmProjects\flask-shop\venv\lib\site-packages\flask\app.py", line 1949, in full_dispatch_request
    rv = self.dispatch_request()
  File "C:\Users\User\PycharmProjects\flask-shop\venv\lib\site-packages\flask\app.py", line 1935, in dispatch_request
    return self.view_functions[rule.endpoint](**req.view_args)
  File "C:\Users\User\PycharmProjects\flask-shop\flask-shop-master\flaskshop\public\views.py", line 30, in home
    return render_template("public/shopHomePage.html", products= products,categories=categories)
  File "C:\Users\User\PycharmProjects\flask-shop\venv\lib\site-packages\flask\templating.py", line 137, in render_template
    return _render(
  File "C:\Users\User\PycharmProjects\flask-shop\venv\lib\site-packages\flask\templating.py", line 120, in _render
    rv = template.render(context)
  File "C:\Users\User\PycharmProjects\flask-shop\venv\lib\site-packages\jinja2\environment.py", line 1090, in render
    self.environment.handle_exception()
  File "C:\Users\User\PycharmProjects\flask-shop\venv\lib\site-packages\jinja2\environment.py", line 832, in handle_exception
    reraise(*rewrite_traceback_stack(source=source))
  File "C:\Users\User\PycharmProjects\flask-shop\venv\lib\site-packages\jinja2\_compat.py", line 28, in reraise
    raise value.with_traceback(tb)
  File "C:\Users\User\PycharmProjects\flask-shop\flask-shop-master\flaskshop\templates\public\shopHomePage.html", line 1, in top-level template code
    {% extends "base.html" %}
  File "C:\Users\User\PycharmProjects\flask-shop\flask-shop-master\flaskshop\templates\base.html", line 109, in top-level template code
    <a href= "{{ item.get_absolute_url()}}" class="single-cat-item">
  File "C:\Users\User\PycharmProjects\flask-shop\flask-shop-master\flaskshop\product\models.py", line 340, in get_absolute_url
    url=url_for("product.show_single", id=self.id)
  File "C:\Users\User\PycharmProjects\flask-shop\venv\lib\site-packages\flask\helpers.py", line 370, in url_for
    return appctx.app.handle_url_build_error(error, endpoint, values)
  File "C:\Users\User\PycharmProjects\flask-shop\venv\lib\site-packages\flask\app.py", line 2215, in handle_url_build_error
    reraise(exc_type, exc_value, tb)
  File "C:\Users\User\PycharmProjects\flask-shop\venv\lib\site-packages\flask\_compat.py", line 39, in reraise
    raise value
  File "C:\Users\User\PycharmProjects\flask-shop\venv\lib\site-packages\flask\helpers.py", line 357, in url_for
    rv = url_adapter.build(
  File "C:\Users\User\PycharmProjects\flask-shop\venv\lib\site-packages\werkzeug\routing.py", line 2020, in build
    raise BuildError(endpoint, values, method, self)
werkzeug.routing.BuildError: Could not build url for endpoint 'product.show_single' with values ['id']. Did you mean 'product.show_a_single_product' instead?
[2022-02-13 22:09:33,197]{C:\Users\User\PycharmProjects\flask-shop\venv\lib\site-packages\flask\app.py:1890}
ERROR - Exception on / [GET]
Traceback (most recent call last):
  File "C:\Users\User\PycharmProjects\flask-shop\venv\lib\site-packages\flask\app.py", line 2446, in wsgi_app
    response = self.full_dispatch_request()
  File "C:\Users\User\PycharmProjects\flask-shop\venv\lib\site-packages\flask\app.py", line 1951, in full_dispatch_request
    rv = self.handle_user_exception(e)
  File "C:\Users\User\PycharmProjects\flask-shop\venv\lib\site-packages\flask_restplus\api.py", line 584, in error_router
    return original_handler(e)
  File "C:\Users\User\PycharmProjects\flask-shop\venv\lib\site-packages\flask\app.py", line 1820, in handle_user_exception
    reraise(exc_type, exc_value, tb)
  File "C:\Users\User\PycharmProjects\flask-shop\venv\lib\site-packages\flask\_compat.py", line 39, in reraise
    raise value
  File "C:\Users\User\PycharmProjects\flask-shop\venv\lib\site-packages\flask\app.py", line 1949, in full_dispatch_request
    rv = self.dispatch_request()
  File "C:\Users\User\PycharmProjects\flask-shop\venv\lib\site-packages\flask\app.py", line 1935, in dispatch_request
    return self.view_functions[rule.endpoint](**req.view_args)
  File "C:\Users\User\PycharmProjects\flask-shop\flask-shop-master\flaskshop\public\views.py", line 30, in home
    return render_template("public/shopHomePage.html", products= products,categories=categories)
  File "C:\Users\User\PycharmProjects\flask-shop\venv\lib\site-packages\flask\templating.py", line 137, in render_template
    return _render(
  File "C:\Users\User\PycharmProjects\flask-shop\venv\lib\site-packages\flask\templating.py", line 120, in _render
    rv = template.render(context)
  File "C:\Users\User\PycharmProjects\flask-shop\venv\lib\site-packages\jinja2\environment.py", line 1090, in render
    self.environment.handle_exception()
  File "C:\Users\User\PycharmProjects\flask-shop\venv\lib\site-packages\jinja2\environment.py", line 832, in handle_exception
    reraise(*rewrite_traceback_stack(source=source))
  File "C:\Users\User\PycharmProjects\flask-shop\venv\lib\site-packages\jinja2\_compat.py", line 28, in reraise
    raise value.with_traceback(tb)
  File "C:\Users\User\PycharmProjects\flask-shop\flask-shop-master\flaskshop\templates\public\shopHomePage.html", line 1, in top-level template code
    {% extends "base.html" %}
  File "C:\Users\User\PycharmProjects\flask-shop\flask-shop-master\flaskshop\templates\base.html", line 222, in top-level template code
    {% block content %}
  File "C:\Users\User\PycharmProjects\flask-shop\flask-shop-master\flaskshop\templates\public\shopHomePage.html", line 46, in block "content"
    {% include('products/item_front_banner.html') %}
  File "C:\Users\User\PycharmProjects\flask-shop\flask-shop-master\flaskshop\templates\products\item_front_banner.html", line 18, in top-level template code
    <h3> <a href="{{ product.get_absolute_url() }}"> <span class="badge badge-secondary  bg-secondary">{{Language["Add to cart"]}}</span></a></h3>
  File "C:\Users\User\PycharmProjects\flask-shop\flask-shop-master\flaskshop\product\models.py", line 53, in get_absolute_url
    return url_for("product.show_single", id=self.id)
  File "C:\Users\User\PycharmProjects\flask-shop\venv\lib\site-packages\flask\helpers.py", line 370, in url_for
    return appctx.app.handle_url_build_error(error, endpoint, values)
  File "C:\Users\User\PycharmProjects\flask-shop\venv\lib\site-packages\flask\app.py", line 2215, in handle_url_build_error
    reraise(exc_type, exc_value, tb)
  File "C:\Users\User\PycharmProjects\flask-shop\venv\lib\site-packages\flask\_compat.py", line 39, in reraise
    raise value
  File "C:\Users\User\PycharmProjects\flask-shop\venv\lib\site-packages\flask\helpers.py", line 357, in url_for
    rv = url_adapter.build(
  File "C:\Users\User\PycharmProjects\flask-shop\venv\lib\site-packages\werkzeug\routing.py", line 2020, in build
    raise BuildError(endpoint, values, method, self)
werkzeug.routing.BuildError: Could not build url for endpoint 'product.show_single' with values ['id']. Did you mean 'product.show_a_single_product' instead?
[2022-02-14 10:54:33,763]{C:\Users\User\PycharmProjects\flask-shop\venv\lib\site-packages\flask\app.py:1890}
ERROR - Exception on /dashboard/products/90/edit [POST]
Traceback (most recent call last):
  File "C:\Users\User\PycharmProjects\flask-shop\venv\lib\site-packages\flask\app.py", line 2446, in wsgi_app
    response = self.full_dispatch_request()
  File "C:\Users\User\PycharmProjects\flask-shop\venv\lib\site-packages\flask\app.py", line 1951, in full_dispatch_request
    rv = self.handle_user_exception(e)
  File "C:\Users\User\PycharmProjects\flask-shop\venv\lib\site-packages\flask_restplus\api.py", line 584, in error_router
    return original_handler(e)
  File "C:\Users\User\PycharmProjects\flask-shop\venv\lib\site-packages\flask\app.py", line 1820, in handle_user_exception
    reraise(exc_type, exc_value, tb)
  File "C:\Users\User\PycharmProjects\flask-shop\venv\lib\site-packages\flask\_compat.py", line 39, in reraise
    raise value
  File "C:\Users\User\PycharmProjects\flask-shop\venv\lib\site-packages\flask\app.py", line 1949, in full_dispatch_request
    rv = self.dispatch_request()
  File "C:\Users\User\PycharmProjects\flask-shop\venv\lib\site-packages\flask\app.py", line 1935, in dispatch_request
    return self.view_functions[rule.endpoint](**req.view_args)
  File "C:\Users\User\PycharmProjects\flask-shop\flask-shop-master\flaskshop\dashboard\views\product.py", line 409, in product_manage
    product_type= product.product_type()
TypeError: 'ProductType' object is not callable
[2022-02-14 10:58:46,584]{C:\Users\User\PycharmProjects\flask-shop\venv\lib\site-packages\flask\app.py:1890}
ERROR - Exception on /dashboard/attributes/1/edit [POST]
Traceback (most recent call last):
  File "C:\Users\User\PycharmProjects\flask-shop\venv\lib\site-packages\urllib3\connection.py", line 156, in _new_conn
    conn = connection.create_connection(
  File "C:\Users\User\PycharmProjects\flask-shop\venv\lib\site-packages\urllib3\util\connection.py", line 61, in create_connection
    for res in socket.getaddrinfo(host, port, family, socket.SOCK_STREAM):
  File "C:\Users\User\AppData\Local\Programs\Python\Python39\lib\socket.py", line 953, in getaddrinfo
    for res in _socket.getaddrinfo(host, port, family, type, proto, flags):
socket.gaierror: [Errno 11001] getaddrinfo failed

During handling of the above exception, another exception occurred:

Traceback (most recent call last):
  File "C:\Users\User\PycharmProjects\flask-shop\venv\lib\site-packages\botocore\httpsession.py", line 385, in send
    urllib_response = conn.urlopen(
  File "C:\Users\User\PycharmProjects\flask-shop\venv\lib\site-packages\urllib3\connectionpool.py", line 719, in urlopen
    retries = retries.increment(
  File "C:\Users\User\PycharmProjects\flask-shop\venv\lib\site-packages\urllib3\util\retry.py", line 376, in increment
    raise six.reraise(type(error), error, _stacktrace)
  File "C:\Users\User\PycharmProjects\flask-shop\venv\lib\site-packages\urllib3\packages\six.py", line 735, in reraise
    raise value
  File "C:\Users\User\PycharmProjects\flask-shop\venv\lib\site-packages\urllib3\connectionpool.py", line 665, in urlopen
    httplib_response = self._make_request(
  File "C:\Users\User\PycharmProjects\flask-shop\venv\lib\site-packages\urllib3\connectionpool.py", line 376, in _make_request
    self._validate_conn(conn)
  File "C:\Users\User\PycharmProjects\flask-shop\venv\lib\site-packages\urllib3\connectionpool.py", line 994, in _validate_conn
    conn.connect()
  File "C:\Users\User\PycharmProjects\flask-shop\venv\lib\site-packages\urllib3\connection.py", line 300, in connect
    conn = self._new_conn()
  File "C:\Users\User\PycharmProjects\flask-shop\venv\lib\site-packages\urllib3\connection.py", line 168, in _new_conn
    raise NewConnectionError(
urllib3.exceptions.NewConnectionError: <botocore.awsrequest.AWSHTTPSConnection object at 0x000001D94D424AC0>: Failed to establish a new connection: [Errno 11001] getaddrinfo failed

During handling of the above exception, another exception occurred:

Traceback (most recent call last):
  File "C:\Users\User\PycharmProjects\flask-shop\venv\lib\site-packages\flask\app.py", line 2446, in wsgi_app
    response = self.full_dispatch_request()
  File "C:\Users\User\PycharmProjects\flask-shop\venv\lib\site-packages\flask\app.py", line 1951, in full_dispatch_request
    rv = self.handle_user_exception(e)
  File "C:\Users\User\PycharmProjects\flask-shop\venv\lib\site-packages\flask_restplus\api.py", line 584, in error_router
    return original_handler(e)
  File "C:\Users\User\PycharmProjects\flask-shop\venv\lib\site-packages\flask\app.py", line 1820, in handle_user_exception
    reraise(exc_type, exc_value, tb)
  File "C:\Users\User\PycharmProjects\flask-shop\venv\lib\site-packages\flask\_compat.py", line 39, in reraise
    raise value
  File "C:\Users\User\PycharmProjects\flask-shop\venv\lib\site-packages\flask\app.py", line 1949, in full_dispatch_request
    rv = self.dispatch_request()
  File "C:\Users\User\PycharmProjects\flask-shop\venv\lib\site-packages\flask\app.py", line 1935, in dispatch_request
    return self.view_functions[rule.endpoint](**req.view_args)
  File "C:\Users\User\PycharmProjects\flask-shop\flask-shop-master\flaskshop\dashboard\views\product.py", line 92, in attributes_manage
    image=upload_file(new_image)
  File "C:\Users\User\PycharmProjects\flask-shop\flask-shop-master\flaskshop\Media\media.py", line 45, in upload_file
    my_bucket.Object(key).put(Body=file)
  File "C:\Users\User\PycharmProjects\flask-shop\venv\lib\site-packages\boto3\resources\factory.py", line 520, in do_action
    response = action(self, *args, **kwargs)
  File "C:\Users\User\PycharmProjects\flask-shop\venv\lib\site-packages\boto3\resources\action.py", line 83, in __call__
    response = getattr(parent.meta.client, operation_name)(*args, **params)
  File "C:\Users\User\PycharmProjects\flask-shop\venv\lib\site-packages\botocore\client.py", line 391, in _api_call
    return self._make_api_call(operation_name, kwargs)
  File "C:\Users\User\PycharmProjects\flask-shop\venv\lib\site-packages\botocore\client.py", line 705, in _make_api_call
    http, parsed_response = self._make_request(
  File "C:\Users\User\PycharmProjects\flask-shop\venv\lib\site-packages\botocore\client.py", line 725, in _make_request
    return self._endpoint.make_request(operation_model, request_dict)
  File "C:\Users\User\PycharmProjects\flask-shop\venv\lib\site-packages\botocore\endpoint.py", line 102, in make_request
    return self._send_request(request_dict, operation_model)
  File "C:\Users\User\PycharmProjects\flask-shop\venv\lib\site-packages\botocore\endpoint.py", line 136, in _send_request
    while self._needs_retry(attempts, operation_model, request_dict,
  File "C:\Users\User\PycharmProjects\flask-shop\venv\lib\site-packages\botocore\endpoint.py", line 252, in _needs_retry
    responses = self._event_emitter.emit(
  File "C:\Users\User\PycharmProjects\flask-shop\venv\lib\site-packages\botocore\hooks.py", line 357, in emit
    return self._emitter.emit(aliased_event_name, **kwargs)
  File "C:\Users\User\PycharmProjects\flask-shop\venv\lib\site-packages\botocore\hooks.py", line 228, in emit
    return self._emit(event_name, kwargs)
  File "C:\Users\User\PycharmProjects\flask-shop\venv\lib\site-packages\botocore\hooks.py", line 211, in _emit
    response = handler(**kwargs)
  File "C:\Users\User\PycharmProjects\flask-shop\venv\lib\site-packages\botocore\retryhandler.py", line 183, in __call__
    if self._checker(attempts, response, caught_exception):
  File "C:\Users\User\PycharmProjects\flask-shop\venv\lib\site-packages\botocore\retryhandler.py", line 250, in __call__
    should_retry = self._should_retry(attempt_number, response,
  File "C:\Users\User\PycharmProjects\flask-shop\venv\lib\site-packages\botocore\retryhandler.py", line 277, in _should_retry
    return self._checker(attempt_number, response, caught_exception)
  File "C:\Users\User\PycharmProjects\flask-shop\venv\lib\site-packages\botocore\retryhandler.py", line 316, in __call__
    checker_response = checker(attempt_number, response,
  File "C:\Users\User\PycharmProjects\flask-shop\venv\lib\site-packages\botocore\retryhandler.py", line 222, in __call__
    return self._check_caught_exception(
  File "C:\Users\User\PycharmProjects\flask-shop\venv\lib\site-packages\botocore\retryhandler.py", line 359, in _check_caught_exception
    raise caught_exception
  File "C:\Users\User\PycharmProjects\flask-shop\venv\lib\site-packages\botocore\endpoint.py", line 199, in _do_get_response
    http_response = self._send(request)
  File "C:\Users\User\PycharmProjects\flask-shop\venv\lib\site-packages\botocore\endpoint.py", line 268, in _send
    return self.http_session.send(request)
  File "C:\Users\User\PycharmProjects\flask-shop\venv\lib\site-packages\botocore\httpsession.py", line 414, in send
    raise EndpointConnectionError(endpoint_url=request.url, error=e)
botocore.exceptions.EndpointConnectionError: Could not connect to the endpoint URL: "https://chayaflaskbacket.s3.amazonaws.com/a_220214_105834_tthr8883hhjsks99jfhfhf564ggaa.webp"
[2022-02-14 11:11:19,432]{C:\Users\User\PycharmProjects\flask-shop\venv\lib\site-packages\flask\app.py:1890}
ERROR - Exception on /products/66/add [POST]
Traceback (most recent call last):
  File "C:\Users\User\PycharmProjects\flask-shop\venv\lib\site-packages\flask\app.py", line 2446, in wsgi_app
    response = self.full_dispatch_request()
  File "C:\Users\User\PycharmProjects\flask-shop\venv\lib\site-packages\flask\app.py", line 1951, in full_dispatch_request
    rv = self.handle_user_exception(e)
  File "C:\Users\User\PycharmProjects\flask-shop\venv\lib\site-packages\flask_restplus\api.py", line 584, in error_router
    return original_handler(e)
  File "C:\Users\User\PycharmProjects\flask-shop\venv\lib\site-packages\flask\app.py", line 1820, in handle_user_exception
    reraise(exc_type, exc_value, tb)
  File "C:\Users\User\PycharmProjects\flask-shop\venv\lib\site-packages\flask\_compat.py", line 39, in reraise
    raise value
  File "C:\Users\User\PycharmProjects\flask-shop\venv\lib\site-packages\flask\app.py", line 1949, in full_dispatch_request
    rv = self.dispatch_request()
  File "C:\Users\User\PycharmProjects\flask-shop\venv\lib\site-packages\flask\app.py", line 1935, in dispatch_request
    return self.view_functions[rule.endpoint](**req.view_args)
  File "C:\Users\User\PycharmProjects\flask-shop\venv\lib\site-packages\flask_login\utils.py", line 261, in decorated_view
    return func(*args, **kwargs)
  File "C:\Users\User\PycharmProjects\flask-shop\flask-shop-master\flaskshop\product\views.py", line 50, in product_add_to_cart
    variant_id = variant.id
AttributeError: 'NoneType' object has no attribute 'id'
[2022-02-14 11:14:54,074]{C:\Users\User\PycharmProjects\flask-shop\venv\lib\site-packages\flask\app.py:1890}
ERROR - Exception on /products/66/add [POST]
Traceback (most recent call last):
  File "C:\Users\User\PycharmProjects\flask-shop\venv\lib\site-packages\flask\app.py", line 2446, in wsgi_app
    response = self.full_dispatch_request()
  File "C:\Users\User\PycharmProjects\flask-shop\venv\lib\site-packages\flask\app.py", line 1951, in full_dispatch_request
    rv = self.handle_user_exception(e)
  File "C:\Users\User\PycharmProjects\flask-shop\venv\lib\site-packages\flask_restplus\api.py", line 584, in error_router
    return original_handler(e)
  File "C:\Users\User\PycharmProjects\flask-shop\venv\lib\site-packages\flask\app.py", line 1820, in handle_user_exception
    reraise(exc_type, exc_value, tb)
  File "C:\Users\User\PycharmProjects\flask-shop\venv\lib\site-packages\flask\_compat.py", line 39, in reraise
    raise value
  File "C:\Users\User\PycharmProjects\flask-shop\venv\lib\site-packages\flask\app.py", line 1949, in full_dispatch_request
    rv = self.dispatch_request()
  File "C:\Users\User\PycharmProjects\flask-shop\venv\lib\site-packages\flask\app.py", line 1935, in dispatch_request
    return self.view_functions[rule.endpoint](**req.view_args)
  File "C:\Users\User\PycharmProjects\flask-shop\venv\lib\site-packages\flask_login\utils.py", line 261, in decorated_view
    return func(*args, **kwargs)
  File "C:\Users\User\PycharmProjects\flask-shop\flask-shop-master\flaskshop\product\views.py", line 50, in product_add_to_cart
    variant_id = variant.id
AttributeError: 'NoneType' object has no attribute 'id'
[2022-02-14 11:45:20,142]{C:\Users\User\PycharmProjects\flask-shop\venv\lib\site-packages\flask\app.py:1890}
ERROR - Exception on /checkout/get_Shipping_address [GET]
Traceback (most recent call last):
  File "C:\Users\User\PycharmProjects\flask-shop\venv\lib\site-packages\flask\app.py", line 2446, in wsgi_app
    response = self.full_dispatch_request()
  File "C:\Users\User\PycharmProjects\flask-shop\venv\lib\site-packages\flask\app.py", line 1951, in full_dispatch_request
    rv = self.handle_user_exception(e)
  File "C:\Users\User\PycharmProjects\flask-shop\venv\lib\site-packages\flask_restplus\api.py", line 584, in error_router
    return original_handler(e)
  File "C:\Users\User\PycharmProjects\flask-shop\venv\lib\site-packages\flask\app.py", line 1820, in handle_user_exception
    reraise(exc_type, exc_value, tb)
  File "C:\Users\User\PycharmProjects\flask-shop\venv\lib\site-packages\flask\_compat.py", line 39, in reraise
    raise value
  File "C:\Users\User\PycharmProjects\flask-shop\venv\lib\site-packages\flask\app.py", line 1949, in full_dispatch_request
    rv = self.dispatch_request()
  File "C:\Users\User\PycharmProjects\flask-shop\venv\lib\site-packages\flask\app.py", line 1935, in dispatch_request
    return self.view_functions[rule.endpoint](**req.view_args)
  File "C:\Users\User\PycharmProjects\flask-shop\flask-shop-master\flaskshop\checkout\views.py", line 126, in get_Shipping_address
    return render_template("account/address_edit.html", form=form, address_id=address_id,show_cart=True)
  File "C:\Users\User\PycharmProjects\flask-shop\venv\lib\site-packages\flask\templating.py", line 137, in render_template
    return _render(
  File "C:\Users\User\PycharmProjects\flask-shop\venv\lib\site-packages\flask\templating.py", line 120, in _render
    rv = template.render(context)
  File "C:\Users\User\PycharmProjects\flask-shop\venv\lib\site-packages\jinja2\environment.py", line 1090, in render
    self.environment.handle_exception()
  File "C:\Users\User\PycharmProjects\flask-shop\venv\lib\site-packages\jinja2\environment.py", line 832, in handle_exception
    reraise(*rewrite_traceback_stack(source=source))
  File "C:\Users\User\PycharmProjects\flask-shop\venv\lib\site-packages\jinja2\_compat.py", line 28, in reraise
    raise value.with_traceback(tb)
  File "C:\Users\User\PycharmProjects\flask-shop\flask-shop-master\flaskshop\templates\account\address_edit.html", line 3, in top-level template code
    {% extends "base.html" %}
  File "C:\Users\User\PycharmProjects\flask-shop\flask-shop-master\flaskshop\templates\base.html", line 222, in top-level template code
    {% block content %}
  File "C:\Users\User\PycharmProjects\flask-shop\flask-shop-master\flaskshop\templates\account\address_edit.html", line 121, in block "content"
    <span>${{current_user_cart.shipping_method.price}}</span>
  File "C:\Users\User\PycharmProjects\flask-shop\venv\lib\site-packages\jinja2\environment.py", line 471, in getattr
    return getattr(obj, attribute)
jinja2.exceptions.UndefinedError: 'None' has no attribute 'shipping_method'
[2022-02-14 12:09:47,624]{C:\Users\User\PycharmProjects\flask-shop\venv\lib\site-packages\flask\app.py:1890}
ERROR - Exception on / [GET]
Traceback (most recent call last):
  File "C:\Users\User\PycharmProjects\flask-shop\venv\lib\site-packages\sqlalchemy\util\_collections.py", line 1020, in __call__
    return self.registry[key]
KeyError: <greenlet.greenlet object at 0x000002C8D43813B0 (otid=0x000002C8D43973C0) current active started main>

During handling of the above exception, another exception occurred:

Traceback (most recent call last):
  File "C:\Users\User\PycharmProjects\flask-shop\venv\lib\site-packages\flask\app.py", line 2446, in wsgi_app
    response = self.full_dispatch_request()
  File "C:\Users\User\PycharmProjects\flask-shop\venv\lib\site-packages\flask\app.py", line 1951, in full_dispatch_request
    rv = self.handle_user_exception(e)
  File "C:\Users\User\PycharmProjects\flask-shop\venv\lib\site-packages\flask_restplus\api.py", line 584, in error_router
    return original_handler(e)
  File "C:\Users\User\PycharmProjects\flask-shop\venv\lib\site-packages\flask\app.py", line 1820, in handle_user_exception
    reraise(exc_type, exc_value, tb)
  File "C:\Users\User\PycharmProjects\flask-shop\venv\lib\site-packages\flask\_compat.py", line 39, in reraise
    raise value
  File "C:\Users\User\PycharmProjects\flask-shop\venv\lib\site-packages\flask\app.py", line 1949, in full_dispatch_request
    rv = self.dispatch_request()
  File "C:\Users\User\PycharmProjects\flask-shop\venv\lib\site-packages\flask\app.py", line 1935, in dispatch_request
    return self.view_functions[rule.endpoint](**req.view_args)
  File "C:\Users\User\PycharmProjects\flask-shop\flask-shop-master\flaskshop\public\views.py", line 26, in home
    products= Product.query.all()
  File "C:\Users\User\PycharmProjects\flask-shop\venv\lib\site-packages\flask_sqlalchemy\__init__.py", line 519, in __get__
    return type.query_class(mapper, session=self.sa.session())
  File "C:\Users\User\PycharmProjects\flask-shop\venv\lib\site-packages\sqlalchemy\orm\scoping.py", line 78, in __call__
    return self.registry()
  File "C:\Users\User\PycharmProjects\flask-shop\venv\lib\site-packages\sqlalchemy\util\_collections.py", line 1022, in __call__
    return self.registry.setdefault(key, self.createfunc())
  File "C:\Users\User\PycharmProjects\flask-shop\venv\lib\site-packages\sqlalchemy\orm\session.py", line 3309, in __call__
    return self.class_(**local_kw)
  File "C:\Users\User\PycharmProjects\flask-shop\venv\lib\site-packages\flask_sqlalchemy\__init__.py", line 138, in __init__
    bind = options.pop('bind', None) or db.engine
  File "C:\Users\User\PycharmProjects\flask-shop\venv\lib\site-packages\flask_sqlalchemy\__init__.py", line 937, in engine
    return self.get_engine()
  File "C:\Users\User\PycharmProjects\flask-shop\venv\lib\site-packages\flask_sqlalchemy\__init__.py", line 956, in get_engine
    return connector.get_engine()
  File "C:\Users\User\PycharmProjects\flask-shop\venv\lib\site-packages\flask_sqlalchemy\__init__.py", line 560, in get_engine
    options = self.get_options(sa_url, echo)
  File "C:\Users\User\PycharmProjects\flask-shop\venv\lib\site-packages\flask_sqlalchemy\__init__.py", line 575, in get_options
    self._sa.apply_driver_hacks(self._app, sa_url, options)
  File "C:\Users\User\PycharmProjects\flask-shop\flask-shop-master\flaskshop\extensions.py", line 147, in apply_driver_hacks
    return super().apply_driver_hacks(app, info, options)
  File "C:\Users\User\PycharmProjects\flask-shop\venv\lib\site-packages\flask_sqlalchemy\__init__.py", line 877, in apply_driver_hacks
    if sa_url.drivername.startswith('mysql'):
AttributeError: 'NoneType' object has no attribute 'drivername'
[2022-02-14 12:15:53,445]{C:\Users\User\PycharmProjects\flask-shop\venv\lib\site-packages\flask\app.py:1890}
ERROR - Exception on / [GET]
Traceback (most recent call last):
  File "C:\Users\User\PycharmProjects\flask-shop\venv\lib\site-packages\sqlalchemy\util\_collections.py", line 1020, in __call__
    return self.registry[key]
KeyError: <greenlet.greenlet object at 0x000001B456BC13B0 (otid=0x000001B456BD8200) current active started main>

During handling of the above exception, another exception occurred:

Traceback (most recent call last):
  File "C:\Users\User\PycharmProjects\flask-shop\venv\lib\site-packages\flask\app.py", line 2446, in wsgi_app
    response = self.full_dispatch_request()
  File "C:\Users\User\PycharmProjects\flask-shop\venv\lib\site-packages\flask\app.py", line 1951, in full_dispatch_request
    rv = self.handle_user_exception(e)
  File "C:\Users\User\PycharmProjects\flask-shop\venv\lib\site-packages\flask_restplus\api.py", line 584, in error_router
    return original_handler(e)
  File "C:\Users\User\PycharmProjects\flask-shop\venv\lib\site-packages\flask\app.py", line 1820, in handle_user_exception
    reraise(exc_type, exc_value, tb)
  File "C:\Users\User\PycharmProjects\flask-shop\venv\lib\site-packages\flask\_compat.py", line 39, in reraise
    raise value
  File "C:\Users\User\PycharmProjects\flask-shop\venv\lib\site-packages\flask\app.py", line 1949, in full_dispatch_request
    rv = self.dispatch_request()
  File "C:\Users\User\PycharmProjects\flask-shop\venv\lib\site-packages\flask\app.py", line 1935, in dispatch_request
    return self.view_functions[rule.endpoint](**req.view_args)
  File "C:\Users\User\PycharmProjects\flask-shop\flask-shop-master\flaskshop\public\views.py", line 26, in home
    products= Product.query.all()
  File "C:\Users\User\PycharmProjects\flask-shop\venv\lib\site-packages\flask_sqlalchemy\__init__.py", line 519, in __get__
    return type.query_class(mapper, session=self.sa.session())
  File "C:\Users\User\PycharmProjects\flask-shop\venv\lib\site-packages\sqlalchemy\orm\scoping.py", line 78, in __call__
    return self.registry()
  File "C:\Users\User\PycharmProjects\flask-shop\venv\lib\site-packages\sqlalchemy\util\_collections.py", line 1022, in __call__
    return self.registry.setdefault(key, self.createfunc())
  File "C:\Users\User\PycharmProjects\flask-shop\venv\lib\site-packages\sqlalchemy\orm\session.py", line 3309, in __call__
    return self.class_(**local_kw)
  File "C:\Users\User\PycharmProjects\flask-shop\venv\lib\site-packages\flask_sqlalchemy\__init__.py", line 138, in __init__
    bind = options.pop('bind', None) or db.engine
  File "C:\Users\User\PycharmProjects\flask-shop\venv\lib\site-packages\flask_sqlalchemy\__init__.py", line 937, in engine
    return self.get_engine()
  File "C:\Users\User\PycharmProjects\flask-shop\venv\lib\site-packages\flask_sqlalchemy\__init__.py", line 956, in get_engine
    return connector.get_engine()
  File "C:\Users\User\PycharmProjects\flask-shop\venv\lib\site-packages\flask_sqlalchemy\__init__.py", line 560, in get_engine
    options = self.get_options(sa_url, echo)
  File "C:\Users\User\PycharmProjects\flask-shop\venv\lib\site-packages\flask_sqlalchemy\__init__.py", line 575, in get_options
    self._sa.apply_driver_hacks(self._app, sa_url, options)
  File "C:\Users\User\PycharmProjects\flask-shop\flask-shop-master\flaskshop\extensions.py", line 147, in apply_driver_hacks
    return super().apply_driver_hacks(app, info, options)
  File "C:\Users\User\PycharmProjects\flask-shop\venv\lib\site-packages\flask_sqlalchemy\__init__.py", line 877, in apply_driver_hacks
    if sa_url.drivername.startswith('mysql'):
AttributeError: 'NoneType' object has no attribute 'drivername'
[2022-02-16 15:17:39,865]{C:\Users\User\PycharmProjects\flask-shop\venv\lib\site-packages\flask\app.py:1890}
ERROR - Exception on / [GET]
Traceback (most recent call last):
  File "C:\Users\User\PycharmProjects\flask-shop\venv\lib\site-packages\flask\app.py", line 2446, in wsgi_app
    response = self.full_dispatch_request()
  File "C:\Users\User\PycharmProjects\flask-shop\venv\lib\site-packages\flask\app.py", line 1951, in full_dispatch_request
    rv = self.handle_user_exception(e)
  File "C:\Users\User\PycharmProjects\flask-shop\venv\lib\site-packages\flask_restplus\api.py", line 584, in error_router
    return original_handler(e)
  File "C:\Users\User\PycharmProjects\flask-shop\venv\lib\site-packages\flask\app.py", line 1820, in handle_user_exception
    reraise(exc_type, exc_value, tb)
  File "C:\Users\User\PycharmProjects\flask-shop\venv\lib\site-packages\flask\_compat.py", line 39, in reraise
    raise value
  File "C:\Users\User\PycharmProjects\flask-shop\venv\lib\site-packages\flask\app.py", line 1949, in full_dispatch_request
    rv = self.dispatch_request()
  File "C:\Users\User\PycharmProjects\flask-shop\venv\lib\site-packages\flask\app.py", line 1935, in dispatch_request
    return self.view_functions[rule.endpoint](**req.view_args)
  File "C:\Users\User\PycharmProjects\flask-shop\flask-shop-master\flaskshop\public\views.py", line 30, in home
    return render_template("public/shopHomePage.html", products= products,categories=categories)
  File "C:\Users\User\PycharmProjects\flask-shop\venv\lib\site-packages\flask\templating.py", line 138, in render_template
    ctx.app.jinja_env.get_or_select_template(template_name_or_list),
  File "C:\Users\User\PycharmProjects\flask-shop\venv\lib\site-packages\jinja2\environment.py", line 930, in get_or_select_template
    return self.get_template(template_name_or_list, parent, globals)
  File "C:\Users\User\PycharmProjects\flask-shop\venv\lib\site-packages\jinja2\environment.py", line 883, in get_template
    return self._load_template(name, self.make_globals(globals))
  File "C:\Users\User\PycharmProjects\flask-shop\venv\lib\site-packages\jinja2\environment.py", line 857, in _load_template
    template = self.loader.load(self, name, globals)
  File "C:\Users\User\PycharmProjects\flask-shop\venv\lib\site-packages\jinja2\loaders.py", line 129, in load
    code = environment.compile(source, name, filename)
  File "C:\Users\User\PycharmProjects\flask-shop\venv\lib\site-packages\jinja2\environment.py", line 638, in compile
    self.handle_exception(source=source_hint)
  File "C:\Users\User\PycharmProjects\flask-shop\venv\lib\site-packages\jinja2\environment.py", line 832, in handle_exception
    reraise(*rewrite_traceback_stack(source=source))
  File "C:\Users\User\PycharmProjects\flask-shop\venv\lib\site-packages\jinja2\_compat.py", line 28, in reraise
    raise value.with_traceback(tb)
  File "C:\Users\User\PycharmProjects\flask-shop\flask-shop-master\flaskshop\templates\public\shopHomePage.html", line 93, in template
    {% endif %}
jinja2.exceptions.TemplateSyntaxError: Encountered unknown tag 'endif'. Jinja was looking for the following tags: 'endfor' or 'else'. The innermost block that needs to be closed is 'for'.
[2022-02-25 15:44:32,686]{C:\Users\User\PycharmProjects\flask-shop\venv\lib\site-packages\flask\app.py:1890}
ERROR - Exception on / [GET]
Traceback (most recent call last):
  File "C:\Users\User\PycharmProjects\flask-shop\venv\lib\site-packages\flask\app.py", line 2446, in wsgi_app
    response = self.full_dispatch_request()
  File "C:\Users\User\PycharmProjects\flask-shop\venv\lib\site-packages\flask\app.py", line 1951, in full_dispatch_request
    rv = self.handle_user_exception(e)
  File "C:\Users\User\PycharmProjects\flask-shop\venv\lib\site-packages\flask_restplus\api.py", line 584, in error_router
    return original_handler(e)
  File "C:\Users\User\PycharmProjects\flask-shop\venv\lib\site-packages\flask\app.py", line 1820, in handle_user_exception
    reraise(exc_type, exc_value, tb)
  File "C:\Users\User\PycharmProjects\flask-shop\venv\lib\site-packages\flask\_compat.py", line 39, in reraise
    raise value
  File "C:\Users\User\PycharmProjects\flask-shop\venv\lib\site-packages\flask\app.py", line 1949, in full_dispatch_request
    rv = self.dispatch_request()
  File "C:\Users\User\PycharmProjects\flask-shop\venv\lib\site-packages\flask\app.py", line 1935, in dispatch_request
    return self.view_functions[rule.endpoint](**req.view_args)
  File "C:\Users\User\PycharmProjects\flask-shop\flask-shop-master\flaskshop\public\views.py", line 29, in home
    categories_arr = categories_arr.reshape(-1, 2)
ValueError: cannot reshape array of size 11 into shape (2)
[2022-02-25 15:45:35,121]{C:\Users\User\PycharmProjects\flask-shop\venv\lib\site-packages\flask\app.py:1890}
ERROR - Exception on / [GET]
Traceback (most recent call last):
  File "C:\Users\User\PycharmProjects\flask-shop\venv\lib\site-packages\flask\app.py", line 2446, in wsgi_app
    response = self.full_dispatch_request()
  File "C:\Users\User\PycharmProjects\flask-shop\venv\lib\site-packages\flask\app.py", line 1951, in full_dispatch_request
    rv = self.handle_user_exception(e)
  File "C:\Users\User\PycharmProjects\flask-shop\venv\lib\site-packages\flask_restplus\api.py", line 584, in error_router
    return original_handler(e)
  File "C:\Users\User\PycharmProjects\flask-shop\venv\lib\site-packages\flask\app.py", line 1820, in handle_user_exception
    reraise(exc_type, exc_value, tb)
  File "C:\Users\User\PycharmProjects\flask-shop\venv\lib\site-packages\flask\_compat.py", line 39, in reraise
    raise value
  File "C:\Users\User\PycharmProjects\flask-shop\venv\lib\site-packages\flask\app.py", line 1949, in full_dispatch_request
    rv = self.dispatch_request()
  File "C:\Users\User\PycharmProjects\flask-shop\venv\lib\site-packages\flask\app.py", line 1935, in dispatch_request
    return self.view_functions[rule.endpoint](**req.view_args)
  File "C:\Users\User\PycharmProjects\flask-shop\flask-shop-master\flaskshop\public\views.py", line 29, in home
    categories_arr = categories_arr.reshape(-1, 2)
ValueError: cannot reshape array of size 11 into shape (2)
[2022-02-25 16:19:17,920]{C:\Users\User\PycharmProjects\flask-shop\venv\lib\site-packages\flask\app.py:1890}
ERROR - Exception on / [GET]
Traceback (most recent call last):
  File "C:\Users\User\PycharmProjects\flask-shop\venv\lib\site-packages\flask\app.py", line 2446, in wsgi_app
    response = self.full_dispatch_request()
  File "C:\Users\User\PycharmProjects\flask-shop\venv\lib\site-packages\flask\app.py", line 1951, in full_dispatch_request
    rv = self.handle_user_exception(e)
  File "C:\Users\User\PycharmProjects\flask-shop\venv\lib\site-packages\flask_restplus\api.py", line 584, in error_router
    return original_handler(e)
  File "C:\Users\User\PycharmProjects\flask-shop\venv\lib\site-packages\flask\app.py", line 1820, in handle_user_exception
    reraise(exc_type, exc_value, tb)
  File "C:\Users\User\PycharmProjects\flask-shop\venv\lib\site-packages\flask\_compat.py", line 39, in reraise
    raise value
  File "C:\Users\User\PycharmProjects\flask-shop\venv\lib\site-packages\flask\app.py", line 1949, in full_dispatch_request
    rv = self.dispatch_request()
  File "C:\Users\User\PycharmProjects\flask-shop\venv\lib\site-packages\flask\app.py", line 1935, in dispatch_request
    return self.view_functions[rule.endpoint](**req.view_args)
  File "C:\Users\User\PycharmProjects\flask-shop\flask-shop-master\flaskshop\public\views.py", line 30, in home
    categories_two_columns= list(zip(categories, categories_copy))
TypeError: 'NoneType' object is not iterable
[2022-02-25 16:21:42,602]{C:\Users\User\PycharmProjects\flask-shop\venv\lib\site-packages\flask\app.py:1890}
ERROR - Exception on / [GET]
Traceback (most recent call last):
  File "C:\Users\User\PycharmProjects\flask-shop\venv\lib\site-packages\flask\app.py", line 2446, in wsgi_app
    response = self.full_dispatch_request()
  File "C:\Users\User\PycharmProjects\flask-shop\venv\lib\site-packages\flask\app.py", line 1951, in full_dispatch_request
    rv = self.handle_user_exception(e)
  File "C:\Users\User\PycharmProjects\flask-shop\venv\lib\site-packages\flask_restplus\api.py", line 584, in error_router
    return original_handler(e)
  File "C:\Users\User\PycharmProjects\flask-shop\venv\lib\site-packages\flask\app.py", line 1820, in handle_user_exception
    reraise(exc_type, exc_value, tb)
  File "C:\Users\User\PycharmProjects\flask-shop\venv\lib\site-packages\flask\_compat.py", line 39, in reraise
    raise value
  File "C:\Users\User\PycharmProjects\flask-shop\venv\lib\site-packages\flask\app.py", line 1949, in full_dispatch_request
    rv = self.dispatch_request()
  File "C:\Users\User\PycharmProjects\flask-shop\venv\lib\site-packages\flask\app.py", line 1935, in dispatch_request
    return self.view_functions[rule.endpoint](**req.view_args)
  File "C:\Users\User\PycharmProjects\flask-shop\flask-shop-master\flaskshop\public\views.py", line 30, in home
    categories_two_columns= list(zip(categories, categories_copy))
TypeError: 'NoneType' object is not iterable
[2022-02-25 17:45:17,303]{C:\Users\User\PycharmProjects\flask-shop\venv\lib\site-packages\flask\app.py:1890}
ERROR - Exception on / [GET]
Traceback (most recent call last):
  File "C:\Users\User\PycharmProjects\flask-shop\venv\lib\site-packages\flask\app.py", line 2446, in wsgi_app
    response = self.full_dispatch_request()
  File "C:\Users\User\PycharmProjects\flask-shop\venv\lib\site-packages\flask\app.py", line 1951, in full_dispatch_request
    rv = self.handle_user_exception(e)
  File "C:\Users\User\PycharmProjects\flask-shop\venv\lib\site-packages\flask_restplus\api.py", line 584, in error_router
    return original_handler(e)
  File "C:\Users\User\PycharmProjects\flask-shop\venv\lib\site-packages\flask\app.py", line 1820, in handle_user_exception
    reraise(exc_type, exc_value, tb)
  File "C:\Users\User\PycharmProjects\flask-shop\venv\lib\site-packages\flask\_compat.py", line 39, in reraise
    raise value
  File "C:\Users\User\PycharmProjects\flask-shop\venv\lib\site-packages\flask\app.py", line 1949, in full_dispatch_request
    rv = self.dispatch_request()
  File "C:\Users\User\PycharmProjects\flask-shop\venv\lib\site-packages\flask\app.py", line 1935, in dispatch_request
    return self.view_functions[rule.endpoint](**req.view_args)
  File "C:\Users\User\PycharmProjects\flask-shop\flask-shop-master\flaskshop\public\views.py", line 32, in home
    return render_template("public/shopHomePage.html", products= products,categories=categories,categories_two_columns=categories_two_columns)
  File "C:\Users\User\PycharmProjects\flask-shop\venv\lib\site-packages\flask\templating.py", line 137, in render_template
    return _render(
  File "C:\Users\User\PycharmProjects\flask-shop\venv\lib\site-packages\flask\templating.py", line 120, in _render
    rv = template.render(context)
  File "C:\Users\User\PycharmProjects\flask-shop\venv\lib\site-packages\jinja2\environment.py", line 1090, in render
    self.environment.handle_exception()
  File "C:\Users\User\PycharmProjects\flask-shop\venv\lib\site-packages\jinja2\environment.py", line 832, in handle_exception
    reraise(*rewrite_traceback_stack(source=source))
  File "C:\Users\User\PycharmProjects\flask-shop\venv\lib\site-packages\jinja2\_compat.py", line 28, in reraise
    raise value.with_traceback(tb)
  File "C:\Users\User\PycharmProjects\flask-shop\flask-shop-master\flaskshop\templates\public\shopHomePage.html", line 1, in top-level template code
    {% extends "base.html" %}
  File "C:\Users\User\PycharmProjects\flask-shop\flask-shop-master\flaskshop\templates\base.html", line 112, in top-level template code
    <img src={{item.get_background_img_AWS ()}} alt="">
  File "C:\Users\User\PycharmProjects\flask-shop\flask-shop-master\flaskshop\product\models.py", line 358, in get_background_img_AWS
    url= get_presigned_url(self.background_img)
  File "C:\Users\User\PycharmProjects\flask-shop\flask-shop-master\flaskshop\resources\resources.py", line 28, in get_presigned_url
    s3_client = boto3.client("s3", aws_access_key_id=current_app.config["S3_KEY"],
  File "C:\Users\User\PycharmProjects\flask-shop\venv\lib\site-packages\boto3\__init__.py", line 93, in client
    return _get_default_session().client(*args, **kwargs)
  File "C:\Users\User\PycharmProjects\flask-shop\venv\lib\site-packages\boto3\session.py", line 270, in client
    return self._session.create_client(
  File "C:\Users\User\PycharmProjects\flask-shop\venv\lib\site-packages\botocore\session.py", line 834, in create_client
    endpoint_resolver = self._get_internal_component('endpoint_resolver')
  File "C:\Users\User\PycharmProjects\flask-shop\venv\lib\site-packages\botocore\session.py", line 707, in _get_internal_component
    return self._internal_components.get_component(name)
  File "C:\Users\User\PycharmProjects\flask-shop\venv\lib\site-packages\botocore\session.py", line 948, in get_component
    del self._deferred[name]
KeyError: 'endpoint_resolver'
[2022-02-25 17:45:17,615]{C:\Users\User\PycharmProjects\flask-shop\venv\lib\site-packages\flask\app.py:1890}
ERROR - Exception on / [GET]
Traceback (most recent call last):
  File "C:\Users\User\PycharmProjects\flask-shop\venv\lib\site-packages\flask\app.py", line 2446, in wsgi_app
    response = self.full_dispatch_request()
  File "C:\Users\User\PycharmProjects\flask-shop\venv\lib\site-packages\flask\app.py", line 1951, in full_dispatch_request
    rv = self.handle_user_exception(e)
  File "C:\Users\User\PycharmProjects\flask-shop\venv\lib\site-packages\flask_restplus\api.py", line 584, in error_router
    return original_handler(e)
  File "C:\Users\User\PycharmProjects\flask-shop\venv\lib\site-packages\flask\app.py", line 1820, in handle_user_exception
    reraise(exc_type, exc_value, tb)
  File "C:\Users\User\PycharmProjects\flask-shop\venv\lib\site-packages\flask\_compat.py", line 39, in reraise
    raise value
  File "C:\Users\User\PycharmProjects\flask-shop\venv\lib\site-packages\flask\app.py", line 1949, in full_dispatch_request
    rv = self.dispatch_request()
  File "C:\Users\User\PycharmProjects\flask-shop\venv\lib\site-packages\flask\app.py", line 1935, in dispatch_request
    return self.view_functions[rule.endpoint](**req.view_args)
  File "C:\Users\User\PycharmProjects\flask-shop\flask-shop-master\flaskshop\public\views.py", line 32, in home
    return render_template("public/shopHomePage.html", products= products,categories=categories,categories_two_columns=categories_two_columns)
  File "C:\Users\User\PycharmProjects\flask-shop\venv\lib\site-packages\flask\templating.py", line 137, in render_template
    return _render(
  File "C:\Users\User\PycharmProjects\flask-shop\venv\lib\site-packages\flask\templating.py", line 120, in _render
    rv = template.render(context)
  File "C:\Users\User\PycharmProjects\flask-shop\venv\lib\site-packages\jinja2\environment.py", line 1090, in render
    self.environment.handle_exception()
  File "C:\Users\User\PycharmProjects\flask-shop\venv\lib\site-packages\jinja2\environment.py", line 832, in handle_exception
    reraise(*rewrite_traceback_stack(source=source))
  File "C:\Users\User\PycharmProjects\flask-shop\venv\lib\site-packages\jinja2\_compat.py", line 28, in reraise
    raise value.with_traceback(tb)
  File "C:\Users\User\PycharmProjects\flask-shop\flask-shop-master\flaskshop\templates\public\shopHomePage.html", line 1, in top-level template code
    {% extends "base.html" %}
  File "C:\Users\User\PycharmProjects\flask-shop\flask-shop-master\flaskshop\templates\base.html", line 112, in top-level template code
    <img src={{item.get_background_img_AWS ()}} alt="">
  File "C:\Users\User\PycharmProjects\flask-shop\flask-shop-master\flaskshop\product\models.py", line 358, in get_background_img_AWS
    url= get_presigned_url(self.background_img)
  File "C:\Users\User\PycharmProjects\flask-shop\flask-shop-master\flaskshop\resources\resources.py", line 28, in get_presigned_url
    s3_client = boto3.client("s3", aws_access_key_id=current_app.config["S3_KEY"],
  File "C:\Users\User\PycharmProjects\flask-shop\venv\lib\site-packages\boto3\__init__.py", line 93, in client
    return _get_default_session().client(*args, **kwargs)
  File "C:\Users\User\PycharmProjects\flask-shop\venv\lib\site-packages\boto3\session.py", line 270, in client
    return self._session.create_client(
  File "C:\Users\User\PycharmProjects\flask-shop\venv\lib\site-packages\botocore\session.py", line 841, in create_client
    client = client_creator.create_client(
  File "C:\Users\User\PycharmProjects\flask-shop\venv\lib\site-packages\botocore\client.py", line 84, in create_client
    cls = self._create_client_class(service_name, service_model)
  File "C:\Users\User\PycharmProjects\flask-shop\venv\lib\site-packages\botocore\client.py", line 117, in _create_client_class
    self._event_emitter.emit(
  File "C:\Users\User\PycharmProjects\flask-shop\venv\lib\site-packages\botocore\hooks.py", line 357, in emit
    return self._emitter.emit(aliased_event_name, **kwargs)
  File "C:\Users\User\PycharmProjects\flask-shop\venv\lib\site-packages\botocore\hooks.py", line 228, in emit
    return self._emit(event_name, kwargs)
  File "C:\Users\User\PycharmProjects\flask-shop\venv\lib\site-packages\botocore\hooks.py", line 211, in _emit
    response = handler(**kwargs)
  File "C:\Users\User\PycharmProjects\flask-shop\venv\lib\site-packages\boto3\utils.py", line 61, in _handler
    module = import_module(module)
  File "C:\Users\User\PycharmProjects\flask-shop\venv\lib\site-packages\boto3\utils.py", line 52, in import_module
    __import__(name)
  File "C:\Users\User\PycharmProjects\flask-shop\venv\lib\site-packages\boto3\s3\inject.py", line 15, in <module>
    from boto3.s3.transfer import create_transfer_manager
  File "C:\Users\User\PycharmProjects\flask-shop\venv\lib\site-packages\boto3\s3\transfer.py", line 127, in <module>
    from s3transfer.exceptions import RetriesExceededError as \
  File "C:\Users\User\PycharmProjects\flask-shop\venv\lib\site-packages\s3transfer\__init__.py", line 353, in <module>
    class MultipartUploader(object):
  File "C:\Users\User\PycharmProjects\flask-shop\venv\lib\site-packages\s3transfer\__init__.py", line 364, in MultipartUploader
    executor_cls=concurrent.futures.ThreadPoolExecutor):
  File "C:\Users\User\AppData\Local\Programs\Python\Python39\lib\concurrent\futures\__init__.py", line 49, in __getattr__
    from .thread import ThreadPoolExecutor as te
  File "C:\Users\User\AppData\Local\Programs\Python\Python39\lib\concurrent\futures\thread.py", line 37, in <module>
    threading._register_atexit(_python_exit)
  File "C:\Users\User\AppData\Local\Programs\Python\Python39\lib\threading.py", line 1374, in _register_atexit
    raise RuntimeError("can't register atexit after shutdown")
RuntimeError: can't register atexit after shutdown
[2022-02-25 18:04:26,062]{C:\Users\User\PycharmProjects\flask-shop\venv\lib\site-packages\flask\app.py:1890}
ERROR - Exception on / [GET]
Traceback (most recent call last):
  File "C:\Users\User\PycharmProjects\flask-shop\venv\lib\site-packages\flask\app.py", line 2446, in wsgi_app
    response = self.full_dispatch_request()
  File "C:\Users\User\PycharmProjects\flask-shop\venv\lib\site-packages\flask\app.py", line 1951, in full_dispatch_request
    rv = self.handle_user_exception(e)
  File "C:\Users\User\PycharmProjects\flask-shop\venv\lib\site-packages\flask_restplus\api.py", line 584, in error_router
    return original_handler(e)
  File "C:\Users\User\PycharmProjects\flask-shop\venv\lib\site-packages\flask\app.py", line 1820, in handle_user_exception
    reraise(exc_type, exc_value, tb)
  File "C:\Users\User\PycharmProjects\flask-shop\venv\lib\site-packages\flask\_compat.py", line 39, in reraise
    raise value
  File "C:\Users\User\PycharmProjects\flask-shop\venv\lib\site-packages\flask\app.py", line 1949, in full_dispatch_request
    rv = self.dispatch_request()
  File "C:\Users\User\PycharmProjects\flask-shop\venv\lib\site-packages\flask\app.py", line 1935, in dispatch_request
    return self.view_functions[rule.endpoint](**req.view_args)
  File "C:\Users\User\PycharmProjects\flask-shop\flask-shop-master\flaskshop\public\views.py", line 32, in home
    return render_template("public/shopHomePage.html", products= products,categories=categories,categories_two_columns=categories_two_columns)
  File "C:\Users\User\PycharmProjects\flask-shop\venv\lib\site-packages\flask\templating.py", line 137, in render_template
    return _render(
  File "C:\Users\User\PycharmProjects\flask-shop\venv\lib\site-packages\flask\templating.py", line 120, in _render
    rv = template.render(context)
  File "C:\Users\User\PycharmProjects\flask-shop\venv\lib\site-packages\jinja2\environment.py", line 1090, in render
    self.environment.handle_exception()
  File "C:\Users\User\PycharmProjects\flask-shop\venv\lib\site-packages\jinja2\environment.py", line 832, in handle_exception
    reraise(*rewrite_traceback_stack(source=source))
  File "C:\Users\User\PycharmProjects\flask-shop\venv\lib\site-packages\jinja2\_compat.py", line 28, in reraise
    raise value.with_traceback(tb)
  File "C:\Users\User\PycharmProjects\flask-shop\flask-shop-master\flaskshop\templates\public\shopHomePage.html", line 1, in top-level template code
    {% extends "base.html" %}
  File "C:\Users\User\PycharmProjects\flask-shop\flask-shop-master\flaskshop\templates\base.html", line 217, in top-level template code
    {% block content %}
  File "C:\Users\User\PycharmProjects\flask-shop\flask-shop-master\flaskshop\templates\public\shopHomePage.html", line 141, in block "content"
    <h5 class="card-title">{{product[0].title}}</h5>
  File "C:\Users\User\PycharmProjects\flask-shop\venv\lib\site-packages\jinja2\environment.py", line 471, in getattr
    return getattr(obj, attribute)
jinja2.exceptions.UndefinedError: flaskshop.product.models.Category object has no element 0
[2022-02-27 18:28:26,554]{C:\Users\User\PycharmProjects\flask-shop\venv\lib\site-packages\flask\app.py:1890}
ERROR - Exception on / [GET]
Traceback (most recent call last):
  File "C:\Users\User\PycharmProjects\flask-shop\venv\lib\site-packages\flask\app.py", line 2446, in wsgi_app
    response = self.full_dispatch_request()
  File "C:\Users\User\PycharmProjects\flask-shop\venv\lib\site-packages\flask\app.py", line 1951, in full_dispatch_request
    rv = self.handle_user_exception(e)
  File "C:\Users\User\PycharmProjects\flask-shop\venv\lib\site-packages\flask_restplus\api.py", line 584, in error_router
    return original_handler(e)
  File "C:\Users\User\PycharmProjects\flask-shop\venv\lib\site-packages\flask\app.py", line 1820, in handle_user_exception
    reraise(exc_type, exc_value, tb)
  File "C:\Users\User\PycharmProjects\flask-shop\venv\lib\site-packages\flask\_compat.py", line 39, in reraise
    raise value
  File "C:\Users\User\PycharmProjects\flask-shop\venv\lib\site-packages\flask\app.py", line 1949, in full_dispatch_request
    rv = self.dispatch_request()
  File "C:\Users\User\PycharmProjects\flask-shop\venv\lib\site-packages\flask\app.py", line 1935, in dispatch_request
    return self.view_functions[rule.endpoint](**req.view_args)
  File "C:\Users\User\PycharmProjects\flask-shop\flask-shop-master\flaskshop\public\views.py", line 30, in home
  File "C:\Users\User\PycharmProjects\flask-shop\venv\lib\site-packages\flask\templating.py", line 138, in render_template
    ctx.app.jinja_env.get_or_select_template(template_name_or_list),
  File "C:\Users\User\PycharmProjects\flask-shop\venv\lib\site-packages\jinja2\environment.py", line 930, in get_or_select_template
    return self.get_template(template_name_or_list, parent, globals)
  File "C:\Users\User\PycharmProjects\flask-shop\venv\lib\site-packages\jinja2\environment.py", line 883, in get_template
    return self._load_template(name, self.make_globals(globals))
  File "C:\Users\User\PycharmProjects\flask-shop\venv\lib\site-packages\jinja2\environment.py", line 857, in _load_template
    template = self.loader.load(self, name, globals)
  File "C:\Users\User\PycharmProjects\flask-shop\venv\lib\site-packages\jinja2\loaders.py", line 129, in load
    code = environment.compile(source, name, filename)
  File "C:\Users\User\PycharmProjects\flask-shop\venv\lib\site-packages\jinja2\environment.py", line 638, in compile
    self.handle_exception(source=source_hint)
  File "C:\Users\User\PycharmProjects\flask-shop\venv\lib\site-packages\jinja2\environment.py", line 832, in handle_exception
    reraise(*rewrite_traceback_stack(source=source))
  File "C:\Users\User\PycharmProjects\flask-shop\venv\lib\site-packages\jinja2\_compat.py", line 28, in reraise
    raise value.with_traceback(tb)
  File "C:\Users\User\PycharmProjects\flask-shop\flask-shop-master\flaskshop\templates\public\shopHomePage.html", line 137, in template
    {% for index in indices[loop.index] %]}                                <div class="cards-wrapper">
jinja2.exceptions.TemplateSyntaxError: unexpected ']'
[2022-02-27 18:29:56,845]{C:\Users\User\PycharmProjects\flask-shop\venv\lib\site-packages\flask\app.py:1890}
ERROR - Exception on / [GET]
Traceback (most recent call last):
  File "C:\Users\User\PycharmProjects\flask-shop\venv\lib\site-packages\flask\app.py", line 2446, in wsgi_app
    response = self.full_dispatch_request()
  File "C:\Users\User\PycharmProjects\flask-shop\venv\lib\site-packages\flask\app.py", line 1951, in full_dispatch_request
    rv = self.handle_user_exception(e)
  File "C:\Users\User\PycharmProjects\flask-shop\venv\lib\site-packages\flask_restplus\api.py", line 584, in error_router
    return original_handler(e)
  File "C:\Users\User\PycharmProjects\flask-shop\venv\lib\site-packages\flask\app.py", line 1820, in handle_user_exception
    reraise(exc_type, exc_value, tb)
  File "C:\Users\User\PycharmProjects\flask-shop\venv\lib\site-packages\flask\_compat.py", line 39, in reraise
    raise value
  File "C:\Users\User\PycharmProjects\flask-shop\venv\lib\site-packages\flask\app.py", line 1949, in full_dispatch_request
    rv = self.dispatch_request()
  File "C:\Users\User\PycharmProjects\flask-shop\venv\lib\site-packages\flask\app.py", line 1935, in dispatch_request
    return self.view_functions[rule.endpoint](**req.view_args)
  File "C:\Users\User\PycharmProjects\flask-shop\flask-shop-master\flaskshop\public\views.py", line 31, in home
    return render_template("public/shopHomePage.html", products= products,categories=categories,indices=indices)
  File "C:\Users\User\PycharmProjects\flask-shop\venv\lib\site-packages\flask\templating.py", line 138, in render_template
    ctx.app.jinja_env.get_or_select_template(template_name_or_list),
  File "C:\Users\User\PycharmProjects\flask-shop\venv\lib\site-packages\jinja2\environment.py", line 930, in get_or_select_template
    return self.get_template(template_name_or_list, parent, globals)
  File "C:\Users\User\PycharmProjects\flask-shop\venv\lib\site-packages\jinja2\environment.py", line 883, in get_template
    return self._load_template(name, self.make_globals(globals))
  File "C:\Users\User\PycharmProjects\flask-shop\venv\lib\site-packages\jinja2\environment.py", line 857, in _load_template
    template = self.loader.load(self, name, globals)
  File "C:\Users\User\PycharmProjects\flask-shop\venv\lib\site-packages\jinja2\loaders.py", line 129, in load
    code = environment.compile(source, name, filename)
  File "C:\Users\User\PycharmProjects\flask-shop\venv\lib\site-packages\jinja2\environment.py", line 638, in compile
    self.handle_exception(source=source_hint)
  File "C:\Users\User\PycharmProjects\flask-shop\venv\lib\site-packages\jinja2\environment.py", line 832, in handle_exception
    reraise(*rewrite_traceback_stack(source=source))
  File "C:\Users\User\PycharmProjects\flask-shop\venv\lib\site-packages\jinja2\_compat.py", line 28, in reraise
    raise value.with_traceback(tb)
  File "C:\Users\User\PycharmProjects\flask-shop\flask-shop-master\flaskshop\templates\public\shopHomePage.html", line 137, in template
    {% for index in indices[loop.index] %]}                                <div class="cards-wrapper">
jinja2.exceptions.TemplateSyntaxError: unexpected ']'
[2022-02-27 18:31:12,443]{C:\Users\User\PycharmProjects\flask-shop\venv\lib\site-packages\flask\app.py:1890}
ERROR - Exception on / [GET]
Traceback (most recent call last):
  File "C:\Users\User\PycharmProjects\flask-shop\venv\lib\site-packages\flask\app.py", line 2446, in wsgi_app
    response = self.full_dispatch_request()
  File "C:\Users\User\PycharmProjects\flask-shop\venv\lib\site-packages\flask\app.py", line 1951, in full_dispatch_request
    rv = self.handle_user_exception(e)
  File "C:\Users\User\PycharmProjects\flask-shop\venv\lib\site-packages\flask_restplus\api.py", line 584, in error_router
    return original_handler(e)
  File "C:\Users\User\PycharmProjects\flask-shop\venv\lib\site-packages\flask\app.py", line 1820, in handle_user_exception
    reraise(exc_type, exc_value, tb)
  File "C:\Users\User\PycharmProjects\flask-shop\venv\lib\site-packages\flask\_compat.py", line 39, in reraise
    raise value
  File "C:\Users\User\PycharmProjects\flask-shop\venv\lib\site-packages\flask\app.py", line 1949, in full_dispatch_request
    rv = self.dispatch_request()
  File "C:\Users\User\PycharmProjects\flask-shop\venv\lib\site-packages\flask\app.py", line 1935, in dispatch_request
    return self.view_functions[rule.endpoint](**req.view_args)
  File "C:\Users\User\PycharmProjects\flask-shop\flask-shop-master\flaskshop\public\views.py", line 31, in home
    return render_template("public/shopHomePage.html", products= products,categories=categories,indices=indices)
  File "C:\Users\User\PycharmProjects\flask-shop\venv\lib\site-packages\flask\templating.py", line 138, in render_template
    ctx.app.jinja_env.get_or_select_template(template_name_or_list),
  File "C:\Users\User\PycharmProjects\flask-shop\venv\lib\site-packages\jinja2\environment.py", line 930, in get_or_select_template
    return self.get_template(template_name_or_list, parent, globals)
  File "C:\Users\User\PycharmProjects\flask-shop\venv\lib\site-packages\jinja2\environment.py", line 883, in get_template
    return self._load_template(name, self.make_globals(globals))
  File "C:\Users\User\PycharmProjects\flask-shop\venv\lib\site-packages\jinja2\environment.py", line 857, in _load_template
    template = self.loader.load(self, name, globals)
  File "C:\Users\User\PycharmProjects\flask-shop\venv\lib\site-packages\jinja2\loaders.py", line 129, in load
    code = environment.compile(source, name, filename)
  File "C:\Users\User\PycharmProjects\flask-shop\venv\lib\site-packages\jinja2\environment.py", line 638, in compile
    self.handle_exception(source=source_hint)
  File "C:\Users\User\PycharmProjects\flask-shop\venv\lib\site-packages\jinja2\environment.py", line 832, in handle_exception
    reraise(*rewrite_traceback_stack(source=source))
  File "C:\Users\User\PycharmProjects\flask-shop\venv\lib\site-packages\jinja2\_compat.py", line 28, in reraise
    raise value.with_traceback(tb)
  File "C:\Users\User\PycharmProjects\flask-shop\flask-shop-master\flaskshop\templates\public\shopHomePage.html", line 137, in template
    {% for index in indices[loop.index] %]}                                <div class="cards-wrapper">
jinja2.exceptions.TemplateSyntaxError: unexpected ']'
[2022-02-27 18:34:05,358]{C:\Users\User\PycharmProjects\flask-shop\venv\lib\site-packages\flask\app.py:1890}
ERROR - Exception on / [GET]
Traceback (most recent call last):
  File "C:\Users\User\PycharmProjects\flask-shop\venv\lib\site-packages\flask\app.py", line 2446, in wsgi_app
    response = self.full_dispatch_request()
  File "C:\Users\User\PycharmProjects\flask-shop\venv\lib\site-packages\flask\app.py", line 1951, in full_dispatch_request
    rv = self.handle_user_exception(e)
  File "C:\Users\User\PycharmProjects\flask-shop\venv\lib\site-packages\flask_restplus\api.py", line 584, in error_router
    return original_handler(e)
  File "C:\Users\User\PycharmProjects\flask-shop\venv\lib\site-packages\flask\app.py", line 1820, in handle_user_exception
    reraise(exc_type, exc_value, tb)
  File "C:\Users\User\PycharmProjects\flask-shop\venv\lib\site-packages\flask\_compat.py", line 39, in reraise
    raise value
  File "C:\Users\User\PycharmProjects\flask-shop\venv\lib\site-packages\flask\app.py", line 1949, in full_dispatch_request
    rv = self.dispatch_request()
  File "C:\Users\User\PycharmProjects\flask-shop\venv\lib\site-packages\flask\app.py", line 1935, in dispatch_request
    return self.view_functions[rule.endpoint](**req.view_args)
  File "C:\Users\User\PycharmProjects\flask-shop\flask-shop-master\flaskshop\public\views.py", line 31, in home
    b = np.insert(a, insert_index, values=a[:, 2], axis=1)
  File "C:\Users\User\PycharmProjects\flask-shop\venv\lib\site-packages\flask\templating.py", line 138, in render_template
    ctx.app.jinja_env.get_or_select_template(template_name_or_list),
  File "C:\Users\User\PycharmProjects\flask-shop\venv\lib\site-packages\jinja2\environment.py", line 930, in get_or_select_template
    return self.get_template(template_name_or_list, parent, globals)
  File "C:\Users\User\PycharmProjects\flask-shop\venv\lib\site-packages\jinja2\environment.py", line 883, in get_template
    return self._load_template(name, self.make_globals(globals))
  File "C:\Users\User\PycharmProjects\flask-shop\venv\lib\site-packages\jinja2\environment.py", line 857, in _load_template
    template = self.loader.load(self, name, globals)
  File "C:\Users\User\PycharmProjects\flask-shop\venv\lib\site-packages\jinja2\loaders.py", line 129, in load
    code = environment.compile(source, name, filename)
  File "C:\Users\User\PycharmProjects\flask-shop\venv\lib\site-packages\jinja2\environment.py", line 638, in compile
    self.handle_exception(source=source_hint)
  File "C:\Users\User\PycharmProjects\flask-shop\venv\lib\site-packages\jinja2\environment.py", line 832, in handle_exception
    reraise(*rewrite_traceback_stack(source=source))
  File "C:\Users\User\PycharmProjects\flask-shop\venv\lib\site-packages\jinja2\_compat.py", line 28, in reraise
    raise value.with_traceback(tb)
  File "C:\Users\User\PycharmProjects\flask-shop\flask-shop-master\flaskshop\templates\public\shopHomePage.html", line 137, in template
    {% for index in indices[loop.index] %]}                                <div class="cards-wrapper">
jinja2.exceptions.TemplateSyntaxError: unexpected ']'
[2022-02-27 18:38:34,005]{C:\Users\User\PycharmProjects\flask-shop\venv\lib\site-packages\flask\app.py:1890}
ERROR - Exception on / [GET]
Traceback (most recent call last):
  File "C:\Users\User\PycharmProjects\flask-shop\venv\lib\site-packages\flask\app.py", line 2446, in wsgi_app
    response = self.full_dispatch_request()
  File "C:\Users\User\PycharmProjects\flask-shop\venv\lib\site-packages\flask\app.py", line 1951, in full_dispatch_request
    rv = self.handle_user_exception(e)
  File "C:\Users\User\PycharmProjects\flask-shop\venv\lib\site-packages\flask_restplus\api.py", line 584, in error_router
    return original_handler(e)
  File "C:\Users\User\PycharmProjects\flask-shop\venv\lib\site-packages\flask\app.py", line 1820, in handle_user_exception
    reraise(exc_type, exc_value, tb)
  File "C:\Users\User\PycharmProjects\flask-shop\venv\lib\site-packages\flask\_compat.py", line 39, in reraise
    raise value
  File "C:\Users\User\PycharmProjects\flask-shop\venv\lib\site-packages\flask\app.py", line 1949, in full_dispatch_request
    rv = self.dispatch_request()
  File "C:\Users\User\PycharmProjects\flask-shop\venv\lib\site-packages\flask\app.py", line 1935, in dispatch_request
    return self.view_functions[rule.endpoint](**req.view_args)
  File "C:\Users\User\PycharmProjects\flask-shop\flask-shop-master\flaskshop\public\views.py", line 33, in home
    return render_template("public/shopHomePage.html", products= products,categories=categories,indices=indices)
  File "C:\Users\User\PycharmProjects\flask-shop\venv\lib\site-packages\flask\templating.py", line 138, in render_template
    ctx.app.jinja_env.get_or_select_template(template_name_or_list),
  File "C:\Users\User\PycharmProjects\flask-shop\venv\lib\site-packages\jinja2\environment.py", line 930, in get_or_select_template
    return self.get_template(template_name_or_list, parent, globals)
  File "C:\Users\User\PycharmProjects\flask-shop\venv\lib\site-packages\jinja2\environment.py", line 883, in get_template
    return self._load_template(name, self.make_globals(globals))
  File "C:\Users\User\PycharmProjects\flask-shop\venv\lib\site-packages\jinja2\environment.py", line 857, in _load_template
    template = self.loader.load(self, name, globals)
  File "C:\Users\User\PycharmProjects\flask-shop\venv\lib\site-packages\jinja2\loaders.py", line 129, in load
    code = environment.compile(source, name, filename)
  File "C:\Users\User\PycharmProjects\flask-shop\venv\lib\site-packages\jinja2\environment.py", line 638, in compile
    self.handle_exception(source=source_hint)
  File "C:\Users\User\PycharmProjects\flask-shop\venv\lib\site-packages\jinja2\environment.py", line 832, in handle_exception
    reraise(*rewrite_traceback_stack(source=source))
  File "C:\Users\User\PycharmProjects\flask-shop\venv\lib\site-packages\jinja2\_compat.py", line 28, in reraise
    raise value.with_traceback(tb)
  File "C:\Users\User\PycharmProjects\flask-shop\flask-shop-master\flaskshop\templates\public\shopHomePage.html", line 137, in template
    {% for index in indices[loop.index] %]}                                <div class="cards-wrapper">
jinja2.exceptions.TemplateSyntaxError: unexpected ']'
[2022-02-27 18:39:22,819]{C:\Users\User\PycharmProjects\flask-shop\venv\lib\site-packages\flask\app.py:1890}
ERROR - Exception on / [GET]
Traceback (most recent call last):
  File "C:\Users\User\PycharmProjects\flask-shop\venv\lib\site-packages\flask\app.py", line 2446, in wsgi_app
    response = self.full_dispatch_request()
  File "C:\Users\User\PycharmProjects\flask-shop\venv\lib\site-packages\flask\app.py", line 1951, in full_dispatch_request
    rv = self.handle_user_exception(e)
  File "C:\Users\User\PycharmProjects\flask-shop\venv\lib\site-packages\flask_restplus\api.py", line 584, in error_router
    return original_handler(e)
  File "C:\Users\User\PycharmProjects\flask-shop\venv\lib\site-packages\flask\app.py", line 1820, in handle_user_exception
    reraise(exc_type, exc_value, tb)
  File "C:\Users\User\PycharmProjects\flask-shop\venv\lib\site-packages\flask\_compat.py", line 39, in reraise
    raise value
  File "C:\Users\User\PycharmProjects\flask-shop\venv\lib\site-packages\flask\app.py", line 1949, in full_dispatch_request
    rv = self.dispatch_request()
  File "C:\Users\User\PycharmProjects\flask-shop\venv\lib\site-packages\flask\app.py", line 1935, in dispatch_request
    return self.view_functions[rule.endpoint](**req.view_args)
  File "C:\Users\User\PycharmProjects\flask-shop\flask-shop-master\flaskshop\public\views.py", line 33, in home
    return render_template("public/shopHomePage.html", products= products,categories=categories,indices=indices)
  File "C:\Users\User\PycharmProjects\flask-shop\venv\lib\site-packages\flask\templating.py", line 138, in render_template
    ctx.app.jinja_env.get_or_select_template(template_name_or_list),
  File "C:\Users\User\PycharmProjects\flask-shop\venv\lib\site-packages\jinja2\environment.py", line 930, in get_or_select_template
    return self.get_template(template_name_or_list, parent, globals)
  File "C:\Users\User\PycharmProjects\flask-shop\venv\lib\site-packages\jinja2\environment.py", line 883, in get_template
    return self._load_template(name, self.make_globals(globals))
  File "C:\Users\User\PycharmProjects\flask-shop\venv\lib\site-packages\jinja2\environment.py", line 857, in _load_template
    template = self.loader.load(self, name, globals)
  File "C:\Users\User\PycharmProjects\flask-shop\venv\lib\site-packages\jinja2\loaders.py", line 129, in load
    code = environment.compile(source, name, filename)
  File "C:\Users\User\PycharmProjects\flask-shop\venv\lib\site-packages\jinja2\environment.py", line 638, in compile
    self.handle_exception(source=source_hint)
  File "C:\Users\User\PycharmProjects\flask-shop\venv\lib\site-packages\jinja2\environment.py", line 832, in handle_exception
    reraise(*rewrite_traceback_stack(source=source))
  File "C:\Users\User\PycharmProjects\flask-shop\venv\lib\site-packages\jinja2\_compat.py", line 28, in reraise
    raise value.with_traceback(tb)
  File "C:\Users\User\PycharmProjects\flask-shop\flask-shop-master\flaskshop\templates\public\shopHomePage.html", line 137, in template
    {% for index in indices[loop.index] %]}                                <div class="cards-wrapper">
jinja2.exceptions.TemplateSyntaxError: unexpected ']'
[2022-02-27 18:39:31,855]{C:\Users\User\PycharmProjects\flask-shop\venv\lib\site-packages\flask\app.py:1890}
ERROR - Exception on / [GET]
Traceback (most recent call last):
  File "C:\Users\User\PycharmProjects\flask-shop\venv\lib\site-packages\flask\app.py", line 2446, in wsgi_app
    response = self.full_dispatch_request()
  File "C:\Users\User\PycharmProjects\flask-shop\venv\lib\site-packages\flask\app.py", line 1951, in full_dispatch_request
    rv = self.handle_user_exception(e)
  File "C:\Users\User\PycharmProjects\flask-shop\venv\lib\site-packages\flask_restplus\api.py", line 584, in error_router
    return original_handler(e)
  File "C:\Users\User\PycharmProjects\flask-shop\venv\lib\site-packages\flask\app.py", line 1820, in handle_user_exception
    reraise(exc_type, exc_value, tb)
  File "C:\Users\User\PycharmProjects\flask-shop\venv\lib\site-packages\flask\_compat.py", line 39, in reraise
    raise value
  File "C:\Users\User\PycharmProjects\flask-shop\venv\lib\site-packages\flask\app.py", line 1949, in full_dispatch_request
    rv = self.dispatch_request()
  File "C:\Users\User\PycharmProjects\flask-shop\venv\lib\site-packages\flask\app.py", line 1935, in dispatch_request
    return self.view_functions[rule.endpoint](**req.view_args)
  File "C:\Users\User\PycharmProjects\flask-shop\flask-shop-master\flaskshop\public\views.py", line 33, in home
    return render_template("public/shopHomePage.html", products= products,categories=categories,indices=indices)
  File "C:\Users\User\PycharmProjects\flask-shop\venv\lib\site-packages\flask\templating.py", line 138, in render_template
    ctx.app.jinja_env.get_or_select_template(template_name_or_list),
  File "C:\Users\User\PycharmProjects\flask-shop\venv\lib\site-packages\jinja2\environment.py", line 930, in get_or_select_template
    return self.get_template(template_name_or_list, parent, globals)
  File "C:\Users\User\PycharmProjects\flask-shop\venv\lib\site-packages\jinja2\environment.py", line 883, in get_template
    return self._load_template(name, self.make_globals(globals))
  File "C:\Users\User\PycharmProjects\flask-shop\venv\lib\site-packages\jinja2\environment.py", line 857, in _load_template
    template = self.loader.load(self, name, globals)
  File "C:\Users\User\PycharmProjects\flask-shop\venv\lib\site-packages\jinja2\loaders.py", line 129, in load
    code = environment.compile(source, name, filename)
  File "C:\Users\User\PycharmProjects\flask-shop\venv\lib\site-packages\jinja2\environment.py", line 638, in compile
    self.handle_exception(source=source_hint)
  File "C:\Users\User\PycharmProjects\flask-shop\venv\lib\site-packages\jinja2\environment.py", line 832, in handle_exception
    reraise(*rewrite_traceback_stack(source=source))
  File "C:\Users\User\PycharmProjects\flask-shop\venv\lib\site-packages\jinja2\_compat.py", line 28, in reraise
    raise value.with_traceback(tb)
  File "C:\Users\User\PycharmProjects\flask-shop\flask-shop-master\flaskshop\templates\public\shopHomePage.html", line 137, in template
    {% for index in indices[loop.index] %]}                                <div class="cards-wrapper">
jinja2.exceptions.TemplateSyntaxError: unexpected ']'
[2022-02-27 18:40:21,773]{C:\Users\User\PycharmProjects\flask-shop\venv\lib\site-packages\flask\app.py:1890}
ERROR - Exception on / [GET]
Traceback (most recent call last):
  File "C:\Users\User\PycharmProjects\flask-shop\venv\lib\site-packages\flask\app.py", line 2446, in wsgi_app
    response = self.full_dispatch_request()
  File "C:\Users\User\PycharmProjects\flask-shop\venv\lib\site-packages\flask\app.py", line 1951, in full_dispatch_request
    rv = self.handle_user_exception(e)
  File "C:\Users\User\PycharmProjects\flask-shop\venv\lib\site-packages\flask_restplus\api.py", line 584, in error_router
    return original_handler(e)
  File "C:\Users\User\PycharmProjects\flask-shop\venv\lib\site-packages\flask\app.py", line 1820, in handle_user_exception
    reraise(exc_type, exc_value, tb)
  File "C:\Users\User\PycharmProjects\flask-shop\venv\lib\site-packages\flask\_compat.py", line 39, in reraise
    raise value
  File "C:\Users\User\PycharmProjects\flask-shop\venv\lib\site-packages\flask\app.py", line 1949, in full_dispatch_request
    rv = self.dispatch_request()
  File "C:\Users\User\PycharmProjects\flask-shop\venv\lib\site-packages\flask\app.py", line 1935, in dispatch_request
    return self.view_functions[rule.endpoint](**req.view_args)
  File "C:\Users\User\PycharmProjects\flask-shop\flask-shop-master\flaskshop\public\views.py", line 33, in home
    return render_template("public/shopHomePage.html", products= products,categories=categories,indices=indices)
  File "C:\Users\User\PycharmProjects\flask-shop\venv\lib\site-packages\flask\templating.py", line 137, in render_template
    return _render(
  File "C:\Users\User\PycharmProjects\flask-shop\venv\lib\site-packages\flask\templating.py", line 120, in _render
    rv = template.render(context)
  File "C:\Users\User\PycharmProjects\flask-shop\venv\lib\site-packages\jinja2\environment.py", line 1090, in render
    self.environment.handle_exception()
  File "C:\Users\User\PycharmProjects\flask-shop\venv\lib\site-packages\jinja2\environment.py", line 832, in handle_exception
    reraise(*rewrite_traceback_stack(source=source))
  File "C:\Users\User\PycharmProjects\flask-shop\venv\lib\site-packages\jinja2\_compat.py", line 28, in reraise
    raise value.with_traceback(tb)
  File "C:\Users\User\PycharmProjects\flask-shop\flask-shop-master\flaskshop\templates\public\shopHomePage.html", line 1, in top-level template code
    {% extends "base.html" %}
  File "C:\Users\User\PycharmProjects\flask-shop\flask-shop-master\flaskshop\templates\base.html", line 217, in top-level template code
    {% block content %}
  File "C:\Users\User\PycharmProjects\flask-shop\flask-shop-master\flaskshop\templates\public\shopHomePage.html", line 138, in block "content"
    {% set item = product[index] %}
  File "C:\Users\User\PycharmProjects\flask-shop\venv\lib\site-packages\jinja2\environment.py", line 452, in getitem
    return obj[argument]
jinja2.exceptions.UndefinedError: 'product' is undefined
[2022-02-27 18:48:20,085]{C:\Users\User\PycharmProjects\flask-shop\venv\lib\site-packages\flask\app.py:1890}
ERROR - Exception on / [GET]
Traceback (most recent call last):
  File "C:\Users\User\PycharmProjects\flask-shop\venv\lib\site-packages\flask\app.py", line 2446, in wsgi_app
    response = self.full_dispatch_request()
  File "C:\Users\User\PycharmProjects\flask-shop\venv\lib\site-packages\flask\app.py", line 1951, in full_dispatch_request
    rv = self.handle_user_exception(e)
  File "C:\Users\User\PycharmProjects\flask-shop\venv\lib\site-packages\flask_restplus\api.py", line 584, in error_router
    return original_handler(e)
  File "C:\Users\User\PycharmProjects\flask-shop\venv\lib\site-packages\flask\app.py", line 1820, in handle_user_exception
    reraise(exc_type, exc_value, tb)
  File "C:\Users\User\PycharmProjects\flask-shop\venv\lib\site-packages\flask\_compat.py", line 39, in reraise
    raise value
  File "C:\Users\User\PycharmProjects\flask-shop\venv\lib\site-packages\flask\app.py", line 1949, in full_dispatch_request
    rv = self.dispatch_request()
  File "C:\Users\User\PycharmProjects\flask-shop\venv\lib\site-packages\flask\app.py", line 1935, in dispatch_request
    return self.view_functions[rule.endpoint](**req.view_args)
  File "C:\Users\User\PycharmProjects\flask-shop\flask-shop-master\flaskshop\public\views.py", line 33, in home
    return render_template("public/shopHomePage.html", products= products,categories=categories,indices=indices)
  File "C:\Users\User\PycharmProjects\flask-shop\venv\lib\site-packages\flask\templating.py", line 138, in render_template
    ctx.app.jinja_env.get_or_select_template(template_name_or_list),
  File "C:\Users\User\PycharmProjects\flask-shop\venv\lib\site-packages\jinja2\environment.py", line 930, in get_or_select_template
    return self.get_template(template_name_or_list, parent, globals)
  File "C:\Users\User\PycharmProjects\flask-shop\venv\lib\site-packages\jinja2\environment.py", line 883, in get_template
    return self._load_template(name, self.make_globals(globals))
  File "C:\Users\User\PycharmProjects\flask-shop\venv\lib\site-packages\jinja2\environment.py", line 857, in _load_template
    template = self.loader.load(self, name, globals)
  File "C:\Users\User\PycharmProjects\flask-shop\venv\lib\site-packages\jinja2\loaders.py", line 129, in load
    code = environment.compile(source, name, filename)
  File "C:\Users\User\PycharmProjects\flask-shop\venv\lib\site-packages\jinja2\environment.py", line 638, in compile
    self.handle_exception(source=source_hint)
  File "C:\Users\User\PycharmProjects\flask-shop\venv\lib\site-packages\jinja2\environment.py", line 832, in handle_exception
    reraise(*rewrite_traceback_stack(source=source))
  File "C:\Users\User\PycharmProjects\flask-shop\venv\lib\site-packages\jinja2\_compat.py", line 28, in reraise
    raise value.with_traceback(tb)
  File "C:\Users\User\PycharmProjects\flask-shop\flask-shop-master\flaskshop\templates\public\shopHomePage.html", line 179, in template
    {% endblock %}
jinja2.exceptions.TemplateSyntaxError: Encountered unknown tag 'endblock'. You probably made a nesting mistake. Jinja is expecting this tag, but currently looking for 'endfor' or 'else'. The innermost block that needs to be closed is 'for'.
[2022-02-28 19:43:49,797]{C:\Users\User\PycharmProjects\flask-shop\venv\lib\site-packages\flask\app.py:1890}
ERROR - Exception on / [GET]
Traceback (most recent call last):
  File "C:\Users\User\PycharmProjects\flask-shop\venv\lib\site-packages\sqlalchemy\util\_collections.py", line 1020, in __call__
    return self.registry[key]
KeyError: <greenlet.greenlet object at 0x00000202AD6D2250 (otid=0x00000202AD6D6340) current active started main>

During handling of the above exception, another exception occurred:

Traceback (most recent call last):
  File "C:\Users\User\PycharmProjects\flask-shop\venv\lib\site-packages\flask\app.py", line 2446, in wsgi_app
    response = self.full_dispatch_request()
  File "C:\Users\User\PycharmProjects\flask-shop\venv\lib\site-packages\flask\app.py", line 1951, in full_dispatch_request
    rv = self.handle_user_exception(e)
  File "C:\Users\User\PycharmProjects\flask-shop\venv\lib\site-packages\flask_restplus\api.py", line 584, in error_router
    return original_handler(e)
  File "C:\Users\User\PycharmProjects\flask-shop\venv\lib\site-packages\flask\app.py", line 1820, in handle_user_exception
    reraise(exc_type, exc_value, tb)
  File "C:\Users\User\PycharmProjects\flask-shop\venv\lib\site-packages\flask\_compat.py", line 39, in reraise
    raise value
  File "C:\Users\User\PycharmProjects\flask-shop\venv\lib\site-packages\flask\app.py", line 1949, in full_dispatch_request
    rv = self.dispatch_request()
  File "C:\Users\User\PycharmProjects\flask-shop\venv\lib\site-packages\flask\app.py", line 1935, in dispatch_request
    return self.view_functions[rule.endpoint](**req.view_args)
  File "C:\Users\User\PycharmProjects\flask-shop\flask-shop-master\flaskshop\public\views.py", line 27, in home
    products = Product.query.all()
  File "C:\Users\User\PycharmProjects\flask-shop\venv\lib\site-packages\flask_sqlalchemy\__init__.py", line 519, in __get__
    return type.query_class(mapper, session=self.sa.session())
  File "C:\Users\User\PycharmProjects\flask-shop\venv\lib\site-packages\sqlalchemy\orm\scoping.py", line 78, in __call__
    return self.registry()
  File "C:\Users\User\PycharmProjects\flask-shop\venv\lib\site-packages\sqlalchemy\util\_collections.py", line 1022, in __call__
    return self.registry.setdefault(key, self.createfunc())
  File "C:\Users\User\PycharmProjects\flask-shop\venv\lib\site-packages\sqlalchemy\orm\session.py", line 3309, in __call__
    return self.class_(**local_kw)
  File "C:\Users\User\PycharmProjects\flask-shop\venv\lib\site-packages\flask_sqlalchemy\__init__.py", line 138, in __init__
    bind = options.pop('bind', None) or db.engine
  File "C:\Users\User\PycharmProjects\flask-shop\venv\lib\site-packages\flask_sqlalchemy\__init__.py", line 937, in engine
    return self.get_engine()
  File "C:\Users\User\PycharmProjects\flask-shop\venv\lib\site-packages\flask_sqlalchemy\__init__.py", line 956, in get_engine
    return connector.get_engine()
  File "C:\Users\User\PycharmProjects\flask-shop\venv\lib\site-packages\flask_sqlalchemy\__init__.py", line 560, in get_engine
    options = self.get_options(sa_url, echo)
  File "C:\Users\User\PycharmProjects\flask-shop\venv\lib\site-packages\flask_sqlalchemy\__init__.py", line 575, in get_options
    self._sa.apply_driver_hacks(self._app, sa_url, options)
  File "C:\Users\User\PycharmProjects\flask-shop\flask-shop-master\flaskshop\extensions.py", line 147, in apply_driver_hacks
    return super().apply_driver_hacks(app, info, options)
  File "C:\Users\User\PycharmProjects\flask-shop\venv\lib\site-packages\flask_sqlalchemy\__init__.py", line 877, in apply_driver_hacks
    if sa_url.drivername.startswith('mysql'):
AttributeError: 'NoneType' object has no attribute 'drivername'
